Workbook

Sheet Règles Indexation
B1: Règle indexation | C1: Mois de revalorisation | D1: Revalorisation | E1: Commentaires
A2: SMIC | B2: IPC du premier quintile et moitié du gain de pouvoir d'achat du salaire horaire moyen des ouvriers et des employés | C2: 1er janvier (1er mai) | D2: 0.9% (2.65%)
A3: Pensions de retraites | B3: Moyenne de l'IPC des 12 derniers mois avant revalo | C3: 1er janvier (avant soit le 1er avril soit le 1er octobre entre 2014 et 2017) | D3: 0.011 | E3: Possible nouvelle indexation le premier juillet de l'ordre de 4.5% (déclaration BLM de début Avril)
A4: RSA | B4: Moyenne de l'IPC des 12 derniers mois avant revalo | C4: 1er Avril | D4: 0.018 | E4: Idem que les pensions de retraites ?
A5: Prime d'activité | B5: Moyenne de l'IPC des 12 derniers mois avant revalo | C5: 1er Avril | D5: 0.018
A6: Allocation logement | B6: Moyenne de l'IPC des 12 derniers mois avant revalo | C6: 1er Avril | D6: 0.018
A7: Prestations familiales | B7: Moyenne de l'IPC des 12 derniers mois avant revalo | C7: 1er Avril | D7: 0.018
A8: Loyers | B8: Indexation à la date d'anniversaire du bail, sur la base de l'IRL du trimestre précédent | C8: Date anniversaire du bail | D8: 2.5% (T1 2022)
B11: 2020-01 | C11: 2020-02 | D11: 2020-03 | E11: 2020-04 | F11: 2020-05 | G11: 2020-06 | H11: 2020-07 | I11: 2020-08 | J11: 2020-09 | K11: 2020-10 | L11: 2020-11 | M11: 2020-12 | N11: 2021-01 | O11: 2021-02 | P11: 2021-03 | Q11: 2021-04 | R11: 2021-05 | S11: 2021-06 | T11: 2021-07 | U11: 2021-08 | V11: 2021-09 | W11: 2021-10 | X11: 2021-11 | Y11: 2021-12 | Z11: 2022-01 | AA11: 2022-02 | AB11: 2022-03 | AC11: 2022-04 | AD11: 2022-05
A12: SMIC | B12: 1219 | C12: 1219 | D12: 1219 | E12: 1219 | F12: 1219 | G12: 1219 | H12: 1219 | I12: 1219 | J12: 1219 | K12: 1219 | L12: 1219 | M12: 1219 | N12: 1231 | O12: 1231 | P12: 1231 | Q12: 1231 | R12: 1231 | S12: 1231 | T12: 1231 | U12: 1231 | V12: 1231 | W12: 1231 | X12: 1231 | Y12: 1231 | Z12: 1269 | AA12: 1269 | AB12: 1269 | AC12: 1269 | AD12: 1302
A13: Pouvoir d'achat du SMIC | B13: 1 | C13: =B13+B13*(C12/B12-Feuil2!NB2/Feuil2!NA2) -> 1.000286 | D13: =C13+C13*(D12/C12-Feuil2!NC2/Feuil2!NB2) -> 1.0044837 | E13: =D13+D13*(E12/D12-Feuil2!ND2/Feuil2!NC2) -> 1.0046761 | F13: =E13+E13*(F12/E12-Feuil2!NE2/Feuil2!ND2) -> 1.0038099 | G13: =F13+F13*(G12/F12-Feuil2!NF2/Feuil2!NE2) -> 1.0028492 | H13: =G13+G13*(H12/G12-Feuil2!NG2/Feuil2!NF2) -> 0.9969997 | I13: =H13+H13*(I12/H12-Feuil2!NH2/Feuil2!NG2) -> 1.0013596 | J13: =I13+I13*(J12/I12-Feuil2!NI2/Feuil2!NH2) -> 1.0022201 | ... AB13: =AA13+AA13*(AB12/AA12-Feuil2!OA2/Feuil2!NZ2) -> 0.98930209
A14: Pouvoir d'achat Pension de retraite | B14: 1

Sheet Feuil1
A1: date | C1: PREST_FAM_TOT | D1: PREST_FAM_AF | E1: PREST_FAM_CF | F1: PREST_FAM_ARS | G1: PREST_FAM_AUTRES | H1: PREST_PAJE_CMG | I1: PREST_PAJE_PREPARE | J1: PREST_PAJE_AUTRES | K1: CHOMAGE | L1: RETRAITES | M1: PREST_PRECARITE_VIEIL | N1: PREST_PRECARITE_HAND | O1: PREST_PRECARITE_RSA | P1: PPA | Q1: PREST_LOGEMENT
A2: 43101 | B2: 100 | C2: 0 | D2: 0 | E2: 0 | F2: 0 | G2: 0 | H2: 0 | I2: 0 | J2: 0 | K2: 0 | L2: =AVERAGE(Feuil2!LO$16:LZ$16) -> 0.0091151711 | M2: 0 | N2: 0 | O2: 0 | P2: 0 | Q2: =Feuil2!U358/100 -> 0
A3: 43132 | B3: =B2+B2*C3 -> 100 | C3: 0 | D3: 0 | E3: 0 | F3: 0 | G3: 0 | H3: 0 | I3: 0 | J3: 0 | K3: 0 | L3: 0 | M3: 0 | N3: 0 | O3: 0 | P3: 0 | Q3: 0
A4: 43160 | B4: =B3+B3*C4 -> 100 | C4: 0 | D4: 0 | E4: 0 | F4: 0 | G4: 0 | H4: 0 | I4: 0 | J4: 0 | K4: 0 | L4: 0 | M4: 0 | N4: 0 | O4: 0 | P4: 0 | Q4: 0
A5: 43191 | B5: =B4+B4*C5 -> 100.98904 | C5: =AVERAGE(Feuil2!LR$16:MC$16) -> 0.0098904069 | D5: =AVERAGE(Feuil2!LR$16:MC$16) -> 0.0098904069 | E5: =AVERAGE(Feuil2!LR$16:MC$16) -> 0.0098904069 | F5: =AVERAGE(Feuil2!LR$16:MC$16) -> 0.0098904069 | G5: =AVERAGE(Feuil2!LR$16:MC$16) -> 0.0098904069 | H5: =AVERAGE(Feuil2!LR$16:MC$16) -> 0.0098904069 | I5: =AVERAGE(Feuil2!LR$16:MC$16) -> 0.0098904069 | J5: =AVERAGE(Feuil2!LR$16:MC$16) -> 0.0098904069 | K5: =AVERAGE(Feuil2!LR$16:MC$16) -> 0.0098904069 | L5: 0 | M5: =AVERAGE(Feuil2!LR$16:MC$16) -> 0.0098904069 | N5: =AVERAGE(Feuil2!LR$16:MC$16) -> 0.0098904069 | O5: =AVERAGE(Feuil2!LR$16:MC$16) -> 0.0098904069 | P5: =AVERAGE(Feuil2!LR$16:MC$16) -> 0.0098904069 | Q5: 0
A6: 43221 | B6: =B5+B5*C6 -> 100.98904 | C6: 0 | D6: 0 | E6: 0 | F6: 0 | G6: 0 | H6: 0 | I6: 0 | J6: 0 | K6: 0 | L6: 0 | M6: 0 | N6: 0 | O6: 0 | P6: 0 | Q6: 0
A7: 43252 | B7: =B6+B6*C7 -> 100.98904 | C7: 0 | D7: 0 | E7: 0 | F7: 0 | G7: 0 | H7: 0 | I7: 0 | J7: 0 | K7: 0 | L7: 0 | M7: 0 | N7: 0 | O7: 0 | P7: 0 | Q7: 0
A8: 43282 | B8: =B7+B7*C8 -> 100.98904 | C8: 0 | D8: 0 | E8: 0 | F8: 0 | G8: 0 | H8: 0 | I8: 0 | J8: 0 | K8: 0 | L8: 0 | M8: 0 | N8: 0 | O8: 0 | P8: 0 | Q8: 0
A9: 43313 | B9: =B8+B8*C9 -> 100.98904 | C9: 0 | D9: 0 | E9: 0 | F9: 0 | G9: 0 | H9: 0 | I9: 0 | J9: 0 | K9: 0 | L9: 0 | M9: 0 | N9: 0 | O9: 0 | P9: 0 | Q9: 0
A10: 43344 | B10: =B9+B9*C10 -> 100.98904 | C10: 0 | D10: 0 | E10: 0 | F10: 0 | G10: 0 | H10: 0 | I10: 0 | J10: 0 | K10: 0 | L10: 0 | M10: 0 | N10: 0 | O10: 0 | P10: 0 | Q10: 0
A11: 43374 | B11: =B10+B10*C11 -> 100.98904 | C11: 0 | D11: 0 | E11: 0 | F11: 0 | G11: 0 | H11: 0 | I11: 0 | J11: 0 | K11: 0 | L11: 0 | M11: 0 | N11: 0 | O11: 0 | P11: 0 | Q11: 0
A12: 43405 | B12: =B11+B11*C12 -> 100.98904 | C12: 0 | D12: 0 | E12: 0 | F12: 0 | G12: 0 | H12: 0 | I12: 0 | J12: 0 | K12: 0 | L12: 0 | M12: 0 | N12: 0 | O12: 0 | P12: 0 | Q12: 0
A13: 43435 | B13: =B12+B12*C13 -> 100.98904 | C13: 0 | D13: 0 | E13: 0 | F13: 0 | G13: 0 | H13: 0 | I13: 0 | J13: 0 | K13: 0 | L13: 0 | M13: 0 | N13: 0 | O13: 0 | P13: 0 | Q13: 0
A14: 43466 | B14: =B13+B13*C14 -> 100.98904 | C14: 0 | D14: 0 | E14: 0 | F14: 0 | G14: 0 | H14: 0 | I14: 0 | J14: 0 | K14: 0 | L14: =AVERAGE(Feuil2!MA$16:ML$16) -> 0.015442958 | M14: 0 | N14: 0 | O14: 0 | P14: 0 | Q14: =Feuil2!U370/100 -> 0
A15: 43497 | B15: =B14+B14*C15 -> 100.98904 | C15: 0 | D15: 0 | E15: 0 | F15: 0 | G15: 0 | H15: 0 | I15: 0 | J15: 0 | K15: 0 | L15: 0 | M15: 0 | N15: 0 | O15: 0 | P15: 0 | Q15: 0
A16: 43525 | B16: =B15+B15*C16 -> 100.98904 | C16: 0 | D16: 0 | E16: 0 | F16: 0 | G16: 0 | H16: 0 | I16: 0 | J16: 0 | K16: 0 | L16: 0 | M16: 0 | N16: 0 | O16: 0 | P16: 0 | Q16: 0
A17: 43556 | B17: =B16+B16*C17 -> 102.59502 | C17: =AVERAGE(Feuil2!MD$16:MO$16) -> 0.015902547 | D17: =AVERAGE(Feuil2!MD$16:MO$16) -> 0.015902547 | E17: =AVERAGE(Feuil2!MD$16:MO$16) -> 0.015902547 | F17: =AVERAGE(Feuil2!MD$16:MO$16) -> 0.015902547 | G17: =AVERAGE(Feuil2!MD$16:MO$16) -> 0.015902547 | H17: =AVERAGE(Feuil2!MD$16:MO$16) -> 0.015902547 | I17: =AVERAGE(Feuil2!MD$16:MO$16) -> 0.015902547 | J17: =AVERAGE(Feuil2!MD$16:MO$16) -> 0.015902547 | K17: =AVERAGE(Feuil2!MD$16:MO$16) -> 0.015902547 | L17: 0 | M17: =AVERAGE(Feuil2!MD$16:MO$16) -> 0.015902547 | N17: =AVERAGE(Feuil2!MD$16:MO$16) -> 0.015902547 | O17: =AVERAGE(Feuil2!MD$16:MO$16) -> 0.015902547 | P17: =AVERAGE(Feuil2!MD$16:MO$16) -> 0.015902547 | Q17: 0
A18: 43586 | B18: =B17+B17*C18 -> 102.59502 | C18: 0 | D18: 0 | E18: 0 | F18: 0 | G18: 0 | H18: 0 | I18: 0 | J18: 0 | K18: 0 | L18: 0 | M18: 0 | N18: 0 | O18: 0 | P18: 0 | Q18: 0
A19: 43617 | B19: =B18+B18*C19 -> 102.59502 | C19: 0 | D19: 0 | E19: 0 | F19: 0 | G19: 0 | H19: 0 | I19: 0 | J19: 0 | K19: 0 | L19: 0 | M19: 0 | N19: 0 | O19: 0 | P19: 0 | Q19: 0
A20: 43647 | B20: =B19+B19*C20 -> 102.59502 | C20: 0 | D20: 0 | E20: 0 | F20: 0 | G20: 0 | H20: 0 | I20: 0 | J20: 0 | K20: 0 | L20: 0 | M20: 0 | N20: 0 | O20: 0 | P20: 0 | Q20: 0
A21: 43678 | B21: =B20+B20*C21 -> 102.59502 | C21: 0 | D21: 0 | E21: 0 | F21: 0 | G21: 0 | H21: 0 | I21: 0 | J21: 0 | K21: 0 | L21: 0 | M21: 0 | N21: 0 | O21: 0 | P21: 0 | Q21: 0
A22: 43709 | B22: =B21+B21*C22 -> 102.59502 | C22: 0 | D22: 0 | E22: 0 | F22: 0 | G22: 0 | H22: 0 | I22: 0 | J22: 0 | K22: 0 | L22: 0 | M22: 0 | N22: 0 | O22: 0 | P22: 0 | Q22: 0
A23: 43739 | B23: =B22+B22*C23 -> 102.59502 | C23: 0 | D23: 0 | E23: 0 | F23: 0 | G23: 0 | H23: 0 | I23: 0 | J23: 0 | K23: 0 | L23: 0 | M23: 0 | N23: 0 | O23: 0 | P23: 0 | Q23: 0
A24: 43770 | B24: =B23+B23*C24 -> 102.59502 | C24: 0 | D24: 0 | E24: 0 | F24: 0 | G24: 0 | H24: 0 | I24: 0 | J24: 0 | K24: 0 | L24: 0 | M24: 0 | N24: 0 | O24: 0 | P24: 0 | Q24: 0
A25: 43800 | B25: =B24+B24*C25 -> 102.59502 | C25: 0 | D25: 0 | E25: 0 | F25: 0 | G25: 0 | H25: 0 | I25: 0 | J25: 0 | K25: 0 | L25: 0 | M25: 0 | N25: 0 | O25: 0 | P25: 0 | Q25: 0
A26: 43831 | B26: =B25+B25*C26 -> 102.59502 | C26: 0 | D26: 0 | E26: 0 | F26: 0 | G26: 0 | H26: 0 | I26: 0 | J26: 0 | K26: 0 | L26: =AVERAGE(Feuil2!MM$16:MX$16) -> 0.010146515 | M26: 0 | N26: 0 | O26: 0 | P26: 0 | Q26: =Feuil2!U382/100 -> 0
A27: 43862 | B27: =B26+B26*C27 -> 102.59502 | C27: 0 | D27: 0 | E27: 0 | F27: 0 | G27: 0 | H27: 0 | I27: 0 | J27: 0 | K27: 0 | L27: 0 | M27: 0 | N27: 0 | O27: 0 | P27: 0 | Q27: 0
A28: 43891 | B28: =B27+B27*C28 -> 102.59502 | C28: 0 | D28: 0 | E28: 0 | F28: 0 | G28: 0 | H28: 0 | I28: 0 | J28: 0 | K28: 0 | L28: 0 | M28: 0 | N28: 0 | O28: 0 | P28: 0 | Q28: 0
A29: 43922 | B29: =B28+B28*C29 -> 103.56593 | C29: =AVERAGE(Feuil2!MP$16:NA$16) -> 0.0094635004 | D29: =AVERAGE(Feuil2!MP$16:NA$16) -> 0.0094635004 | E29: =AVERAGE(Feuil2!MP$16:NA$16) -> 0.0094635004 | F29: =AVERAGE(Feuil2!MP$16:NA$16) -> 0.0094635004 | G29: =AVERAGE(Feuil2!MP$16:NA$16) -> 0.0094635004 | H29: =AVERAGE(Feuil2!MP$16:NA$16) -> 0.0094635004 | I29: =AVERAGE(Feuil2!MP$16:NA$16) -> 0.0094635004 | J29: =AVERAGE(Feuil2!MP$16:NA$16) -> 0.0094635004 | K29: =AVERAGE(Feuil2!MP$16:NA$16) -> 0.0094635004 | L29: 0 | M29: =AVERAGE(Feuil2!MP$16:NA$16) -> 0.0094635004 | N29: =AVERAGE(Feuil2!MP$16:NA$16) -> 0.0094635004 | O29: =AVERAGE(Feuil2!MP$16:NA$16) -> 0.0094635004 | P29: =AVERAGE(Feuil2!MP$16:NA$16) -> 0.0094635004 | Q29: 0
A30: 43952 | B30: =B29+B29*C30 -> 103.56593 | C30: 0 | D30: 0 | E30: 0 | F30: 0 | G30: 0 | H30: 0 | I30: 0 | J30: 0 | K30: 0 | L30: 0 | M30: 0 | N30: 0 | O30: 0 | P30: 0 | Q30: 0
A31: 43983 | B31: =B30+B30*C31 -> 103.56593 | C31: 0 | D31: 0 | E31: 0 | F31: 0 | G31: 0 | H31: 0 | I31: 0 | J31: 0 | K31: 0 | L31: 0 | M31: 0 | N31: 0 | O31: 0 | P31: 0 | Q31: 0
A32: 44013 | B32: =B31+B31*C32 -> 103.56593 | C32: 0 | D32: 0 | E32: 0 | F32: 0 | G32: 0 | H32: 0 | I32: 0 | J32: 0 | K32: 0 | L32: 0 | M32: 0 | N32: 0 | O32: 0 | P32: 0 | Q32: 0
A33: 44044 | B33: =B32+B32*C33 -> 103.56593 | C33: 0 | D33: 0 | E33: 0 | F33: 0 | G33: 0 | H33: 0 | I33: 0 | J33: 0 | K33: 0 | L33: 0 | M33: 0 | N33: 0 | O33: 0 | P33: 0 | Q33: 0
A34: 44075 | B34: =B33+B33*C34 -> 103.56593 | C34: 0 | D34: 0 | E34: 0 | F34: 0 | G34: 0 | H34: 0 | I34: 0 | J34: 0 | K34: 0 | L34: 0 | M34: 0 | N34: 0 | O34: 0 | P34: 0 | Q34: 0
A35: 44105 | B35: =B34+B34*C35 -> 103.56593 | C35: 0 | D35: 0 | E35: 0 | F35: 0 | G35: 0 | H35: 0 | I35: 0 | J35: 0 | K35: 0 | L35: 0 | M35: 0 | N35: 0 | O35: 0 | P35: 0 | Q35: 0
A36: 44136 | B36: =B35+B35*C36 -> 103.56593 | C36: 0 | D36: 0 | E36: 0 | F36: 0 | G36: 0 | H36: 0 | I36: 0 | J36: 0 | K36: 0 | L36: 0 | M36: 0 | N36: 0 | O36: 0 | P36: 0 | Q36: 0
A37: 44166 | B37: =B36+B36*C37 -> 103.56593 | C37: 0 | D37: 0 | E37: 0 | F37: 0 | G37: 0 | H37: 0 | I37: 0 | J37: 0 | K37: 0 | L37: 0 | M37: 0 | N37: 0 | O37: 0 | P37: 0 | Q37: 0
A38: 44197 | B38: =B37+B37*C38 -> 103.56593 | C38: 0 | D38: 0 | E38: 0 | F38: 0 | G38: 0 | H38: 0 | I38: 0 | J38: 0 | K38: 0 | L38: =AVERAGE(Feuil2!MY$16:NJ$16) -> 0.0040073782 | M38: 0 | N38: 0 | O38: 0 | P38: 0 | Q38: =Feuil2!U394/100 -> 0
A39: 44228 | B39: =B38+B38*C39 -> 103.56593 | C39: 0 | D39: 0 | E39: 0 | F39: 0 | G39: 0 | H39: 0 | I39: 0 | J39: 0 | K39: 0 | L39: 0 | M39: 0 | N39: 0 | O39: 0 | P39: 0 | Q39: 0
A40: 44256 | B40: =B39+B39*C40 -> 103.56593 | C40: 0 | D40: 0 | E40: 0 | F40: 0 | G40: 0 | H40: 0 | I40: 0 | J40: 0 | K40: 0 | L40: 0 | M40: 0 | N40: 0 | O40: 0 | P40: 0 | Q40: 0
...

Sheet Feuil2
A1: Libellé | B1: idBank | C1: Dernière mise à jour | D1: Période | E1: 1990-01 | F1: 1990-02 | G1: 1990-03 | H1: 1990-04 | I1: 1990-05 | J1: 1990-06 | K1: 1990-07 | L1: 1990-08 | M1: 1990-09 | N1: 1990-10 | O1: 1990-11 | P1: 1990-12 | Q1: 1991-01 | R1: 1991-02 | S1: 1991-03 | T1: 1991-04 | U1: 1991-05 | V1: 1991-06 | W1: 1991-07 | X1: 1991-08 | Y1: 1991-09 | Z1: 1991-10 | AA1: 1991-11 | AB1: 1991-12 | AC1: 1992-01 | AD1: 1992-02 | AE1: 1992-03 | AF1: 1992-04 | AG1: 1992-05 | AH1: 1992-06 | AI1: 1992-07 | AJ1: 1992-08 | AK1: 1992-09 | AL1: 1992-10 | AM1: 1992-11 | AN1: 1992-12 | AO1: 1993-01 | AP1: 1993-02 | AQ1: 1993-03 | AR1: 1993-04 | AS1: 1993-05 | AT1: 1993-06 | AU1: 1993-07 | AV1: 1993-08 | AW1: 1993-09 | AX1: 1993-10 | AY1: 1993-11 | AZ1: 1993-12 | BA1: 1994-01 | BB1: 1994-02 | BC1: 1994-03 | BD1: 1994-04 | BE1: 1994-05 | BF1: 1994-06 | BG1: 1994-07 | BH1: 1994-08 | BI1: 1994-09 | BJ1: 1994-10 | BK1: 1994-11 | BL1: 1994-12 | BM1: 1995-01 | BN1: 1995-02 | BO1: 1995-03 | BP1: 1995-04 | BQ1: 1995-05 | BR1: 1995-06 | BS1: 1995-07 | BT1: 1995-08 | BU1: 1995-09 | BV1: 1995-10 | BW1: 1995-11 | BX1: 1995-12 | BY1: 1996-01 | BZ1: 1996-02 | CA1: 1996-03 | CB1: 1996-04 | CC1: 1996-05 | CD1: 1996-06 | CE1: 1996-07 | CF1: 1996-08 | CG1: 1996-09 | CH1: 1996-10 | CI1: 1996-11 | CJ1: 1996-12 | CK1: 1997-01 | CL1: 1997-02 | CM1: 1997-03 | CN1: 1997-04 | CO1: 1997-05 | CP1: 1997-06 | CQ1: 1997-07 | CR1: 1997-08 | CS1: 1997-09 | CT1: 1997-10 | CU1: 1997-11 | CV1: 1997-12 | CW1: 1998-01 | CX1: 1998-02 | CY1: 1998-03 | CZ1: 1998-04 | DA1: 1998-05 | DB1: 1998-06 | DC1: 1998-07 | DD1: 1998-08 | DE1: 1998-09 | DF1: 1998-10 | DG1: 1998-11 | DH1: 1998-12 | DI1: 1999-01 | DJ1: 1999-02 | DK1: 1999-03 | DL1: 1999-04 | DM1: 1999-05 | DN1: 1999-06 | DO1: 1999-07 | DP1: 1999-08 | DQ1: 1999-09 | DR1: 1999-10 | DS1: 1999-11 | DT1: 1999-12 | DU1: 2000-01 | DV1: 2000-02 | DW1: 2000-03 | DX1: 2000-04 | DY1: 2000-05 | DZ1: 2000-06 | EA1: 2000-07 | EB1: 2000-08 | EC1: 2000-09 | ED1: 2000-10 | EE1: 2000-11 | EF1: 2000-12 | EG1: 2001-01 | EH1: 2001-02 | EI1: 2001-03 | EJ1: 2001-04 | EK1: 2001-05 | EL1: 2001-06 | EM1: 2001-07 | EN1: 2001-08 | EO1: 2001-09 | EP1: 2001-10 | EQ1: 2001-11 | ER1: 2001-12 | ES1: 2002-01 | ET1: 2002-02 | EU1: 2002-03 | EV1: 2002-04 | EW1: 2002-05 | EX1: 2002-06 | EY1: 2002-07 | EZ1: 2002-08 | FA1: 2002-09 | FB1: 2002-10 | FC1: 2002-11 | FD1: 2002-12 | FE1: 2003-01 | FF1: 2003-02 | FG1: 2003-03 | FH1: 2003-04 | FI1: 2003-05 | FJ1: 2003-06 | FK1: 2003-07 | FL1: 2003-08 | FM1: 2003-09 | FN1: 2003-10 | FO1: 2003-11 | FP1: 2003-12 | FQ1: 2004-01 | FR1: 2004-02 | FS1: 2004-03 | FT1: 2004-04 | FU1: 2004-05 | FV1: 2004-06 | FW1: 2004-07 | FX1: 2004-08 | FY1: 2004-09 | FZ1: 2004-10 | GA1: 2004-11 | GB1: 2004-12 | GC1: 2005-01 | GD1: 2005-02 | GE1: 2005-03 | GF1: 2005-04 | GG1: 2005-05 | GH1: 2005-06 | GI1: 2005-07 | GJ1: 2005-08 | GK1: 2005-09 | GL1: 2005-10 | GM1: 2005-11 | GN1: 2005-12 | GO1: 2006-01 | GP1: 2006-02 | GQ1: 2006-03 | GR1: 2006-04 | GS1: 2006-05 | GT1: 2006-06 | GU1: 2006-07 | GV1: 2006-08 | GW1: 2006-09 | GX1: 2006-10 | GY1: 2006-11 | GZ1: 2006-12 | HA1: 2007-01 | HB1: 2007-02 | HC1: 2007-03 | HD1: 2007-04 | HE1: 2007-05 | HF1: 2007-06 | HG1: 2007-07 | HH1: 2007-08 | HI1: 2007-09 | HJ1: 2007-10 | HK1: 2007-11 | HL1: 2007-12 | HM1: 2008-01 | HN1: 2008-02 | HO1: 2008-03 | HP1: 2008-04 | HQ1: 2008-05 | HR1: 2008-06 | HS1: 2008-07 | HT1: 2008-08 | HU1: 2008-09 | HV1: 2008-10 | HW1: 2008-11 | HX1: 2008-12 | HY1: 2009-01 | HZ1: 2009-02 | IA1: 2009-03 | IB1: 2009-04 | IC1: 2009-05 | ID1: 2009-06 | IE1: 2009-07 | IF1: 2009-08 | IG1: 2009-09 | IH1: 2009-10 | II1: 2009-11 | IJ1: 2009-12 | IK1: 2010-01 | IL1: 2010-02 | IM1: 2010-03 | IN1: 2010-04 | IO1: 2010-05 | IP1: 2010-06 | IQ1: 2010-07 | IR1: 2010-08 | IS1: 2010-09 | IT1: 2010-10 | IU1: 2010-11 | IV1: 2010-12 | IW1: 2011-01 | IX1: 2011-02 | IY1: 2011-03 | IZ1: 2011-04 | JA1: 2011-05 | JB1: 2011-06 | JC1: 2011-07 | JD1: 2011-08 | JE1: 2011-09 | JF1: 2011-10 | JG1: 2011-11 | JH1: 2011-12 | JI1: 2012-01 | JJ1: 2012-02 | JK1: 2012-03 | JL1: 2012-04 | JM1: 2012-05 | JN1: 2012-06 | JO1: 2012-07 | JP1: 2012-08 | JQ1: 2012-09 | JR1: 2012-10 | JS1: 2012-11 | JT1: 2012-12 | JU1: 2013-01 | JV1: 2013-02 | JW1: 2013-03 | JX1: 2013-04 | JY1: 2013-05 | JZ1: 2013-06 | KA1: 2013-07 | KB1: 2013-08 | KC1: 2013-09 | KD1: 2013-10 | KE1: 2013-11 | KF1: 2013-12 | KG1: 2014-01 | KH1: 2014-02 | KI1: 2014-03 | KJ1: 2014-04 | KK1: 2014-05 | KL1: 2014-06 | KM1: 2014-07 | KN1: 2014-08 | KO1: 2014-09 | KP1: 2014-10 | KQ1: 2014-11 | KR1: 2014-12 | KS1: 2015-01 | KT1: 2015-02 | KU1: 2015-03 | KV1: 2015-04 | KW1: 2015-05 | KX1: 2015-06 | KY1: 2015-07 | KZ1: 2015-08 | LA1: 2015-09 | LB1: 2015-10 | LC1: 2015-11 | LD1: 2015-12 | LE1: 2016-01 | LF1: 2016-02 | LG1: 2016-03 | LH1: 2016-04 | LI1: 2016-05 | LJ1: 2016-06 | LK1: 2016-07 | LL1: 2016-08 | LM1: 2016-09 | LN1: 2016-10 | LO1: 2016-11 | LP1: 2016-12 | LQ1: 2017-01 | LR1: 2017-02 | LS1: 2017-03 | LT1: 2017-04 | LU1: 2017-05 | LV1: 2017-06 | LW1: 2017-07 | LX1: 2017-08 | LY1: 2017-09 | LZ1: 2017-10 | MA1: 2017-11 | MB1: 2017-12 | MC1: 2018-01 | MD1: 2018-02 | ME1: 2018-03 | MF1: 2018-04 | MG1: 2018-05 | MH1: 2018-06 | MI1: 2018-07 | MJ1: 2018-08 | MK1: 2018-09 | ML1: 2018-10 | MM1: 2018-11 | MN1: 2018-12 | MO1: 2019-01 | MP1: 2019-02 | MQ1: 2019-03 | MR1: 2019-04 | MS1: 2019-05 | MT1: 2019-06 | MU1: 2019-07 | MV1: 2019-08 | MW1: 2019-09 | MX1: 2019-10 | MY1: 2019-11 | MZ1: 2019-12 | NA1: 2020-01 | NB1: 2020-02 | NC1: 2020-03 | ND1: 2020-04 | NE1: 2020-05 | NF1: 2020-06 | NG1: 2020-07 | NH1: 2020-08 | NI1: 2020-09 | NJ1: 2020-10 | NK1: 2020-11 | NL1: 2020-12 | NM1: 2021-01 | NN1: 2021-02 | NO1: 2021-03 | NP1: 2021-04 | NQ1: 2021-05 | NR1: 2021-06 | NS1: 2021-07 | NT1: 2021-08 | NU1: 2021-09 | NV1: 2021-10 | NW1: 2021-11 | NX1: 2021-12 | NY1: 2022-01 | NZ1: 2022-02 | OA1: 2022-03
A2: Indice CVS des prix à la consommation - Base 2015 - Ensemble des ménages - France - Ensemble | B2: 001769682 | C2: 15/04/2022 08:45 | E2: 66.6 | F2: 66.6 | G2: 66.6 | H2: 67 | I2: 67 | J2: 67.2 | K2: 67.3 | L2: 67.8 | M2: 68.2 | N2: 68.4 | O2: 68.4 | P2: 68.4 | Q2: 68.8 | R2: 68.8 | S2: 68.8 | T2: 69.1 | U2: 69.2 | V2: 69.5 | W2: 69.8 | X2: 70 | Y2: 70 | Z2: 70.3 | AA2: 70.6 | AB2: 70.6 | AC2: 70.6 | AD2: 70.8 | AE2: 70.9 | AF2: 71 | AG2: 71.2 | AH2: 71.3 | AI2: 71.3 | AJ2: 71.4 | AK2: 71.5 | AL2: 71.6 | AM2: 71.8 | AN2: 71.9 | AO2: 72 | AP2: 72.2 | AQ2: 72.4 | AR2: 72.5 | AS2: 72.6 | AT2: 72.7 | AU2: 72.8 | AV2: 73 | AW2: 73.1 | AX2: 73.2 | AY2: 73.3 | AZ2: 73.4 | BA2: 73.4 | BB2: 73.4 | BC2: 73.4 | BD2: 73.7 | BE2: 73.8 | BF2: 73.9 | BG2: 74.1 | BH2: 74.1 | BI2: 74.2 | BJ2: 74.4 | BK2: 74.4 | BL2: 74.5 | BM2: 74.7 | BN2: 74.8 | BO2: 74.9 | BP2: 74.9 | BQ2: 75 | BR2: 75.2 | BS2: 75.2 | BT2: 75.6 | BU2: 75.7 | BV2: 75.8 | BW2: 76 | BX2: 76 | BY2: 76.2 | BZ2: 76.3 | CA2: 76.6 | CB2: 76.7 | CC2: 76.8 | CD2: 76.9 | CE2: 76.9 | CF2: 76.7 | CG2: 76.9 | CH2: 77.1 | CI2: 77.1 | CJ2: 77.3 | CK2: 77.5 | CL2: 77.5 | CM2: 77.4 | CN2: 77.4 | CO2: 77.5 | CP2: 77.6 | CQ2: 77.7 | CR2: 77.8 | CS2: 77.9 | CT2: 77.9 | CU2: 78.1 | CV2: 78.1 | CW2: 78 | CX2: 78.1 | CY2: 78.1 | CZ2: 78.2 | DA2: 78.2 | DB2: 78.3 | DC2: 78.3 | DD2: 78.3 | DE2: 78.2 | DF2: 78.2 | DG2: 78.2 | DH2: 78.3 | DI2: 78.2 | DJ2: 78.4 | DK2: 78.4 | DL2: 78.5 | DM2: 78.5 | DN2: 78.5 | DO2: 78.6 | DP2: 78.7 | DQ2: 78.8 | DR2: 78.8 | DS2: 79 | DT2: 79.2 | DU2: 79.5 | DV2: 79.5 | DW2: 79.6 | DX2: 79.4 | DY2: 79.5 | DZ2: 79.8 | EA2: 79.9 | EB2: 80 | EC2: 80.4 | ED2: 80.3 | EE2: 80.7 | EF2: 80.7 | EG2: 80.4 | EH2: 80.5 | EI2: 80.6 | EJ2: 80.9 | EK2: 81.3 | EL2: 81.4 | EM2: 81.5 | EN2: 81.5 | EO2: 81.6 | EP2: 81.7 | EQ2: 81.6 | ER2: 81.8 | ES2: 82.2 | ET2: 82.2 | EU2: 82.3 | EV2: 82.5 | EW2: 82.5 | EX2: 82.6 | EY2: 82.8 | EZ2: 83 | FA2: 83.1 | FB2: 83.2 | FC2: 83.4 | FD2: 83.6 | FE2: 83.9 | FF2: 84.3 | FG2: 84.4 | FH2: 84.2 | FI2: 84 | FJ2: 84.2 | FK2: 84.4 | FL2: 84.5 | FM2: 84.8 | FN2: 85 | FO2: 85.3 | FP2: 85.4 | FQ2: 85.5 | FR2: 85.8 | FS2: 85.9 | FT2: 85.9 | FU2: 86.2 | FV2: 86.3 | FW2: 86.4 | FX2: 86.5 | FY2: 86.6 | FZ2: 86.8 | GA2: 87 | GB2: 87.1 | GC2: 86.8 | GD2: 87.2 | GE2: 87.6 | GF2: 87.6 | GG2: 87.5 | GH2: 87.7 | GI2: 87.8 | GJ2: 88.1 | GK2: 88.5 | GL2: 88.5 | GM2: 88.4 | GN2: 88.5 | GO2: 88.68 | GP2: 88.85 | GQ2: 88.87 | GR2: 89.06 | GS2: 89.32 | GT2: 89.36 | GU2: 89.54 | GV2: 89.7 | GW2: 89.59 | GX2: 89.47 | GY2: 89.61 | GZ2: 89.78 | HA2: 89.81 | HB2: 89.79 | HC2: 89.93 | HD2: 90.18 | HE2: 90.26 | HF2: 90.39 | HG2: 90.53 | HH2: 90.74 | HI2: 90.97 | HJ2: 91.3 | HK2: 91.83 | HL2: 92.09 | HM2: 92.37 | HN2: 92.34 | HO2: 92.76 | HP2: 92.89 | HQ2: 93.25 | HR2: 93.6 | HS2: 93.81 | HT2: 93.6 | HU2: 93.71 | HV2: 93.76 | HW2: 93.34 | HX2: 93.01 | HY2: 93.03 | HZ2: 93.12 | IA2: 92.98 | IB2: 92.99 | IC2: 93.01 | ID2: 93.14 | IE2: 93.15 | IF2: 93.43 | IG2: 93.41 | IH2: 93.58 | II2: 93.73 | IJ2: 93.83 | IK2: 94.06 | IL2: 94.3 | IM2: 94.38 | IN2: 94.54 | IO2: 94.57 | IP2: 94.57 | IQ2: 94.74 | IR2: 94.72 | IS2: 94.9 | IT2: 95.06 | IU2: 95.22 | IV2: 95.47 | IW2: 95.71 | IX2: 95.86 | IY2: 96.21 | IZ2: 96.5 | JA2: 96.51 | JB2: 96.61 | JC2: 96.6 | JD2: 96.82 | JE2: 97.04 | JF2: 97.28 | JG2: 97.62 | JH2: 97.81 | JI2: 97.98 | JJ2: 98.06 | JK2: 98.39 | JL2: 98.51 | JM2: 98.43 | JN2: 98.5 | JO2: 98.47 | JP2: 98.8 | JQ2: 98.89 | JR2: 99.06 | JS2: 99 | JT2: 99.1 | JU2: 99.17 | JV2: 99.11 | JW2: 99.35 | JX2: 99.21 | JY2: 99.23 | JZ2: 99.42 | KA2: 99.51 | KB2: 99.63 | KC2: 99.76 | KD2: 99.62 | KE2: 99.71 | KF2: 99.85 | KG2: 99.82 | KH2: 100.02 | KI2: 99.93 | KJ2: 99.91 | KK2: 99.91 | KL2: 99.89 | KM2: 99.95 | KN2: 100.01 | KO2: 99.99 | KP2: 99.98 | KQ2: 99.95 | KR2: 99.85 | KS2: 99.39 | KT2: 99.88 | KU2: 99.96 | KV2: 100.07 | KW2: 100.18 | KX2: 100.15 | KY2: 100.11 | KZ2: 100.06 | LA2: 100 | LB2: 100.06 | LC2: 100.01 | LD2: 100.08 | LE2: 99.6 | LF2: 99.74 | LG2: 99.84 | LH2: 99.89 | LI2: 100.16 | LJ2: 100.33 | LK2: 100.31 | LL2: 100.28 | LM2: 100.39 | LN2: 100.43 | LO2: 100.54 | LP2: 100.71 | LQ2: 100.89 | LR2: 100.96 | LS2: 101.01 | LT2: 101.07 | LU2: 100.98 | LV2: 101.03 | LW2: 101.01 | LX2: 101.18 | LY2: 101.37 | LZ2: 101.5 | MA2: 101.71 | MB2: 101.9 | MC2: 102.2 | MD2: 102.14 | ME2: 102.59 | MF2: 102.73 | MG2: 103.06 | MH2: 103.1 | MI2: 103.31 | MJ2: 103.45 | MK2: 103.62 | ML2: 103.76 | MM2: 103.6 | MN2: 103.51 | MO2: 103.41 | MP2: 103.45 | MQ2: 103.74 | MR2: 104.06 | MS2: 104.07 | MT2: 104.34 | MU2: 104.4 | MV2: 104.53 | MW2: 104.61 | MX2: 104.59 | MY2: 104.68 | MZ2: 105.05 | NA2: 104.88 | NB2: 104.85 | NC2: 104.41 | ND2: 104.39 | NE2: 104.48 | NF2: 104.58 | NG2: 105.19 | NH2: 104.73 | NI2: 104.64 | NJ2: 104.6 | NK2: 104.78 | NL2: 104.91 | NM2: 105.45 | NN2: 105.44 | NO2: 105.58 | NP2: 105.75 | NQ2: 105.98 | NR2: 106.18 | NS2: 106.52 | NT2: 106.86 | NU2: 106.85 | NV2: 107.33 | NW2: 107.6 | NX2: 107.8 | NY2: 108.49 | NZ2: 109.29 | OA2: 110.35
A3: Indice des prix à la consommation - Base 2015 - Ensemble des ménages - France - Ensemble hors énergie | B3: 001763851 | C3: 15/04/2022 08:45 | E3: 67.84 | F3: 68.03 | G3: 68.23 | H3: 68.66 | I3: 68.78 | J3: 68.8 | K3: 68.82 | L3: 69.01 | M3: 69.2 | N3: 69.38 | O3: 69.46 | P3: 69.54 | Q3: 69.95 | R3: 70.18 | S3: 70.44 | T3: 70.71 | U3: 70.92 | V3: 71.08 | W3: 71.26 | X3: 71.31 | Y3: 71.42 | Z3: 71.82 | AA3: 72.08 | AB3: 71.89 | AC3: 72.1 | AD3: 72.43 | AE3: 72.69 | AF3: 72.87 | AG3: 73.12 | AH3: 73.06 | AI3: 73.03 | AJ3: 73 | AK3: 73.27 | AL3: 73.47 | AM3: 73.53 | AN3: 73.5 | AO3: 73.81 | AP3: 74.06 | AQ3: 74.44 | AR3: 74.52 | AS3: 74.64 | AT3: 74.61 | AU3: 74.55 | AV3: 74.48 | AW3: 74.73 | AX3: 74.88 | AY3: 74.94 | AZ3: 74.94 | BA3: 75.04 | BB3: 75.26 | BC3: 75.46 | BD3: 75.67 | BE3: 75.85 | BF3: 75.82 | BG3: 75.82 | BH3: 75.78 | BI3: 76.06 | BJ3: 76.25 | BK3: 76.26 | BL3: 76.24 | BM3: 76.37 | BN3: 76.59 | BO3: 76.86 | BP3: 76.96 | BQ3: 77.06 | BR3: 77.06 | BS3: 76.95 | BT3: 77.26 | BU3: 77.53 | BV3: 77.62 | BW3: 77.69 | BX3: 77.73 | BY3: 77.74 | BZ3: 78.02 | CA3: 78.52 | CB3: 78.56 | CC3: 78.72 | CD3: 78.68 | CE3: 78.53 | CF3: 78.36 | CG3: 78.53 | CH3: 78.63 | CI3: 78.53 | CJ3: 78.68 | CK3: 78.81 | CL3: 78.99 | CM3: 79.12 | CN3: 79.21 | CO3: 79.36 | CP3: 79.37 | CQ3: 79.28 | CR3: 79.42 | CS3: 79.58 | CT3: 79.52 | CU3: 79.62 | CV3: 79.67 | CW3: 79.44 | CX3: 79.78 | CY3: 79.99 | CZ3: 80.17 | DA3: 80.28 | DB3: 80.4 | DC3: 80.14 | DD3: 80.23 | DE3: 80.21 | DF3: 80.14 | DG3: 80.12 | DH3: 80.24 | DI3: 80.05 | DJ3: 80.32 | DK3: 80.57 | DL3: 80.71 | DM3: 80.75 | DN3: 80.76 | DO3: 80.44 | DP3: 80.48 | DQ3: 80.54 | DR3: 80.55 | DS3: 80.55 | DT3: 80.71 | DU3: 80.64 | DV3: 80.69 | DW3: 80.98 | DX3: 81.06 | DY3: 81.16 | DZ3: 81.26 | EA3: 81.08 | EB3: 81.25 | EC3: 81.37 | ED3: 81.44 | EE3: 81.53 | EF3: 81.63 | EG3: 81.6 | EH3: 81.79 | EI3: 82.2 | EJ3: 82.56 | EK3: 82.9 | EL3: 82.96 | EM3: 82.91 | EN3: 83.02 | EO3: 83.12 | EP3: 83.27 | EQ3: 83.13 | ER3: 83.36 | ES3: 83.78 | ET3: 83.89 | EU3: 84.22 | EV3: 84.42 | EW3: 84.56 | EX3: 84.63 | EY3: 84.66 | EZ3: 84.78 | FA3: 84.86 | FB3: 84.94 | FC3: 85.01 | FD3: 85.15 | FE3: 85.18 | FF3: 85.68 | FG3: 85.94 | FH3: 86.1 | FI3: 86.18 | FJ3: 86.39 | FK3: 86.22 | FL3: 86.39 | FM3: 86.72 | FN3: 86.92 | FO3: 87.05 | FP3: 87.16 | FQ3: 87.09 | FR3: 87.52 | FS3: 87.77 | FT3: 87.97 | FU3: 88.11 | FV3: 88.23 | FW3: 88.06 | FX3: 88.12 | FY3: 88.19 | FZ3: 88.22 | GA3: 88.25 | GB3: 88.44 | GC3: 88.05 | GD3: 88.52 | GE3: 88.94 | GF3: 88.98 | GG3: 89.15 | GH3: 89.12 | GI3: 88.76 | GJ3: 89.03 | GK3: 89.13 | GL3: 89.09 | GM3: 89.13 | GN3: 89.37 | GO3: 89.14 | GP3: 89.47 | GQ3: 89.71 | GR3: 89.93 | GS3: 90.18 | GT3: 90.23 | GU3: 90 | GV3: 90.28 | GW3: 90.28 | GX3: 90.31 | GY3: 90.47 | GZ3: 90.68 | HA3: 90.4 | HB3: 90.57 | HC3: 90.87 | HD3: 91.22 | HE3: 91.37 | HF3: 91.46 | HG3: 91.17 | HH3: 91.61 | HI3: 91.67 | HJ3: 91.87 | HK3: 92.07 | HL3: 92.41 | HM3: 92.23 | HN3: 92.48 | HO3: 93.02 | HP3: 93.28 | HQ3: 93.48 | HR3: 93.56 | HS3: 93.32 | HT3: 93.57 | HU3: 93.54 | HV3: 93.8 | HW3: 93.77 | HX3: 93.96 | HY3: 93.7 | HZ3: 94.05 | IA3: 94.38 | IB3: 94.54 | IC3: 94.68 | ID3: 94.59 | IE3: 94.21 | IF3: 94.59 | IG3: 94.39 | IH3: 94.51 | II3: 94.5 | IJ3: 94.81 | IK3: 94.38 | IL3: 94.95 | IM3: 95.29 | IN3: 95.35 | IO3: 95.39 | IP3: 95.43 | IQ3: 95.14 | IR3: 95.38 | IS3: 95.26 | IT3: 95.32 | IU3: 95.36 | IV3: 95.67 | IW3: 95.12 | IX3: 95.51 | IY3: 96.15 | IZ3: 96.39 | JA3: 96.57 | JB3: 96.69 | JC3: 96.23 | JD3: 96.74 | JE3: 96.59 | JF3: 96.84 | JG3: 97.02 | JH3: 97.45 | JI3: 96.86 | JJ3: 97.2 | JK3: 97.98 | JL3: 98.11 | JM3: 98.2 | JN3: 98.44 | JO3: 97.95 | JP3: 98.32 | JQ3: 98.08 | JR3: 98.33 | JS3: 98.28 | JT3: 98.64 | JU3: 97.93 | JV3: 98.11 | JW3: 98.94 | JX3: 98.88 | JY3: 99.1 | JZ3: 99.27 | KA3: 98.92 | KB3: 99.3 | KC3: 98.97 | KD3: 98.99 | KE3: 98.99 | KF3: 99.3 | KG3: 98.61 | KH3: 99.2 | KI3: 99.74 | KJ3: 99.71 | KK3: 99.75 | KL3: 99.71 | KM3: 99.36 | KN3: 99.91 | KO3: 99.51 | KP3: 99.58 | KQ3: 99.45 | KR3: 99.77 | KS3: 98.87 | KT3: 99.39 | KU3: 100.02 | KV3: 100.12 | KW3: 100.3 | KX3: 100.26 | KY3: 99.91 | KZ3: 100.43 | LA3: 100.08 | LB3: 100.2 | LC3: 100.03 | LD3: 100.38 | LE3: 99.44 | LF3: 99.79 | LG3: 100.47 | LH3: 100.52 | LI3: 100.79 | LJ3: 100.74 | LK3: 100.45 | LL3: 100.94 | LM3: 100.61 | LN3: 100.53 | LO3: 100.44 | LP3: 100.69 | LQ3: 100.05 | LR3: 100.18 | LS3: 100.93 | LT3: 101.05 | LU3: 101.23 | LV3: 101.33 | LW3: 101.05 | LX3: 101.52 | LY3: 101.26 | LZ3: 101.28 | MA3: 101.27 | MB3: 101.57 | MC3: 101.06 | MD3: 101.03 | ME3: 102.2 | MF3: 102.3 | MG3: 102.6 | MH3: 102.54 | MI3: 102.39 | MJ3: 102.93 | MK3: 102.61 | ML3: 102.56 | MM3: 102.39 | MN3: 102.63 | MO3: 102.25 | MP3: 102.19 | MQ3: 102.98 | MR3: 103.29 | MS3: 103.34 | MT3: 103.63 | MU3: 103.51 | MV3: 104.03 | MW3: 103.61 | MX3: 103.56 | MY3: 103.61 | MZ3: 104.03 | NA3: 103.51 | NB3: 103.68 | NC3: 104.1 | ND3: 104.42 | NE3: 104.76 | NF3: 104.7 | NG3: 105.04 | NH3: 104.92 | NI3: 104.39 | NJ3: 104.33 | NK3: 104.54 | NL3: 104.64 | NM3: 104.67 | NN3: 104.45 | NO3: 104.95 | NP3: 105.1 | NQ3: 105.41 | NR3: 105.47 | NS3: 105.33 | NT3: 105.97 | NU3: 105.59 | NV3: 105.61 | NW3: 105.88 | NX3: 106.2 | NY3: 106.19 | NZ3: 106.7 | OA3: 107.38
A4: Indice des prix à la consommation - Base 2015 - Ensemble des ménages - France - Ensemble hors tabac | B4: 001763852 | C4: 15/04/2022 08:45 | E4: 68.09 | F4: 68.23 | G4: 68.4 | H4: 68.78 | I4: 68.89 | J4: 68.88 | K4: 68.9 | L4: 69.36 | M4: 69.86 | N4: 70.17 | O4: 70.05 | P4: 70 | Q4: 70.39 | R4: 70.58 | S4: 70.72 | T4: 70.94 | U4: 71.17 | V4: 71.34 | W4: 71.53 | X4: 71.62 | Y4: 71.73 | Z4: 72.06 | AA4: 72.33 | AB4: 72.1 | AC4: 72.22 | AD4: 72.53 | AE4: 72.77 | AF4: 72.91 | AG4: 73.07 | AH4: 73.02 | AI4: 72.99 | AJ4: 72.94 | AK4: 73.16 | AL4: 73.35 | AM4: 73.43 | AN4: 73.39 | AO4: 73.62 | AP4: 73.81 | AQ4: 74.19 | AR4: 74.28 | AS4: 74.37 | AT4: 74.27 | AU4: 74.34 | AV4: 74.33 | AW4: 74.57 | AX4: 74.71 | AY4: 74.78 | AZ4: 74.75 | BA4: 74.73 | BB4: 74.9 | BC4: 75.07 | BD4: 75.28 | BE4: 75.45 | BF4: 75.42 | BG4: 75.4 | BH4: 75.4 | BI4: 75.64 | BJ4: 75.8 | BK4: 75.73 | BL4: 75.69 | BM4: 75.89 | BN4: 76.13 | BO4: 76.37 | BP4: 76.46 | BQ4: 76.57 | BR4: 76.58 | BS4: 76.44 | BT4: 76.72 | BU4: 77 | BV4: 77.08 | BW4: 77.15 | BX4: 77.21 | BY4: 77.26 | BZ4: 77.55 | CA4: 78.06 | CB4: 78.15 | CC4: 78.31 | CD4: 78.22 | CE4: 78.07 | CF4: 77.92 | CG4: 78.16 | CH4: 78.37 | CI4: 78.3 | CJ4: 78.41 | CK4: 78.52 | CL4: 78.67 | CM4: 78.74 | CN4: 78.77 | CO4: 78.88 | CP4: 78.87 | CQ4: 78.76 | CR4: 78.97 | CS4: 79.11 | CT4: 79.07 | CU4: 79.21 | CV4: 79.24 | CW4: 78.95 | CX4: 79.25 | CY4: 79.39 | CZ4: 79.55 | DA4: 79.57 | DB4: 79.63 | DC4: 79.36 | DD4: 79.42 | DE4: 79.39 | DF4: 79.34 | DG4: 79.29 | DH4: 79.38 | DI4: 79.08 | DJ4: 79.33 | DK4: 79.6 | DL4: 79.83 | DM4: 79.83 | DN4: 79.83 | DO4: 79.61 | DP4: 79.74 | DQ4: 79.87 | DR4: 79.93 | DS4: 79.96 | DT4: 80.32 | DU4: 80.25 | DV4: 80.35 | DW4: 80.73 | DX4: 80.73 | DY4: 80.9 | DZ4: 81.1 | EA4: 80.97 | EB4: 81.13 | EC4: 81.55 | ED4: 81.45 | EE4: 81.63 | EF4: 81.6 | EG4: 81.18 | EH4: 81.39 | EI4: 81.76 | EJ4: 82.16 | EK4: 82.68 | EL4: 82.73 | EM4: 82.56 | EN4: 82.56 | EO4: 82.71 | EP4: 82.76 | EQ4: 82.53 | ER4: 82.63 | ES4: 82.89 | ET4: 82.99 | EU4: 83.36 | EV4: 83.68 | EW4: 83.79 | EX4: 83.78 | EY4: 83.78 | EZ4: 83.98 | FA4: 84.14 | FB4: 84.27 | FC4: 84.27 | FD4: 84.41 | FE4: 84.42 | FF4: 84.99 | FG4: 85.33 | FH4: 85.21 | FI4: 85.12 | FJ4: 85.28 | FK4: 85.19 | FL4: 85.39 | FM4: 85.73 | FN4: 85.78 | FO4: 85.67 | FP4: 85.76 | FQ4: 85.61 | FR4: 85.96 | FS4: 86.3 | FT4: 86.53 | FU4: 86.85 | FV4: 86.89 | FW4: 86.75 | FX4: 86.94 | FY4: 87.02 | FZ4: 87.26 | GA4: 87.3 | GB4: 87.4 | GC4: 86.91 | GD4: 87.46 | GE4: 88.02 | GF4: 88.19 | GG4: 88.25 | GH4: 88.35 | GI4: 88.22 | GJ4: 88.56 | GK4: 88.91 | GL4: 88.89 | GM4: 88.71 | GN4: 88.82 | GO4: 88.73 | GP4: 89.07 | GQ4: 89.33 | GR4: 89.71 | GS4: 90.11 | GT4: 90.1 | GU4: 89.95 | GV4: 90.26 | GW4: 90.05 | GX4: 89.85 | GY4: 89.96 | GZ4: 90.16 | HA4: 89.85 | HB4: 90.02 | HC4: 90.41 | HD4: 90.86 | HE4: 91.09 | HF4: 91.2 | HG4: 90.97 | HH4: 91.26 | HI4: 91.34 | HJ4: 91.58 | HK4: 92.09 | HL4: 92.44 | HM4: 92.33 | HN4: 92.53 | HO4: 93.24 | HP4: 93.56 | HQ4: 94.07 | HR4: 94.42 | HS4: 94.21 | HT4: 94.17 | HU4: 94.11 | HV4: 94.05 | HW4: 93.6 | HX4: 93.37 | HY4: 92.98 | HZ4: 93.34 | IA4: 93.52 | IB4: 93.66 | IC4: 93.81 | ID4: 93.93 | IE4: 93.5 | IF4: 93.99 | IG4: 93.76 | IH4: 93.85 | II4: 93.91 | IJ4: 94.14 | IK4: 93.92 | IL4: 94.45 | IM4: 94.92 | IN4: 95.18 | IO4: 95.28 | IP4: 95.27 | IQ4: 95 | IR4: 95.23 | IS4: 95.15 | IT4: 95.28 | IU4: 95.32 | IV4: 95.74 | IW4: 95.51 | IX4: 95.97 | IY4: 96.76 | IZ4: 97.1 | JA4: 97.16 | JB4: 97.23 | JC4: 96.79 | JD4: 97.31 | JE4: 97.23 | JF4: 97.42 | JG4: 97.64 | JH4: 98.04 | JI4: 97.68 | JJ4: 98.09 | JK4: 98.93 | JL4: 99.06 | JM4: 99 | JN4: 99.04 | JO4: 98.6 | JP4: 99.27 | JQ4: 99.01 | JR4: 99.07 | JS4: 98.91 | JT4: 99.23 | JU4: 98.71 | JV4: 99 | JW4: 99.77 | JX4: 99.62 | JY4: 99.67 | JZ4: 99.84 | KA4: 99.5 | KB4: 99.94 | KC4: 99.7 | KD4: 99.57 | KE4: 99.52 | KF4: 99.87 | KG4: 99.26 | KH4: 99.79 | KI4: 100.25 | KJ4: 100.2 | KK4: 100.23 | KL4: 100.19 | KM4: 99.87 | KN4: 100.31 | KO4: 99.92 | KP4: 99.95 | KQ4: 99.78 | KR4: 99.86 | KS4: 98.85 | KT4: 99.51 | KU4: 100.17 | KV4: 100.29 | KW4: 100.53 | KX4: 100.45 | KY4: 100.03 | KZ4: 100.36 | LA4: 99.95 | LB4: 100.01 | LC4: 99.81 | LD4: 100.04 | LE4: 99.07 | LF4: 99.32 | LG4: 100.02 | LH4: 100.09 | LI4: 100.51 | LJ4: 100.64 | LK4: 100.26 | LL4: 100.59 | LM4: 100.35 | LN4: 100.37 | LO4: 100.36 | LP4: 100.66 | LQ4: 100.41 | LR4: 100.52 | LS4: 101.14 | LT4: 101.23 | LU4: 101.28 | LV4: 101.3 | LW4: 100.94 | LX4: 101.47 | LY4: 101.3 | LZ4: 101.4 | MA4: 101.47 | MB4: 101.76 | MC4: 101.67 | MD4: 101.64 | ME4: 102.42 | MF4: 102.59 | MG4: 103.06 | MH4: 103.07 | MI4: 102.96 | MJ4: 103.48 | MK4: 103.25 | ML4: 103.37 | MM4: 103.14 | MN4: 103.16 | MO4: 102.67 | MP4: 102.73 | MQ4: 103.43 | MR4: 103.76 | MS4: 103.86 | MT4: 104.12 | MU4: 103.91 | MV4: 104.4 | MW4: 104.04 | MX4: 103.99 | MY4: 103.92 | MZ4: 104.39 | NA4: 103.94 | NB4: 103.93 | NC4: 103.85 | ND4: 103.81 | NE4: 103.95 | NF4: 104.04 | NG4: 104.44 | NH4: 104.34 | NI4: 103.8 | NJ4: 103.75 | NK4: 103.86 | NL4: 104.09 | NM4: 104.24 | NN4: 104.24 | NO4: 104.89 | NP4: 105 | NQ4: 105.34 | NR4: 105.48 | NS4: 105.55 | NT4: 106.21 | NU4: 105.97 | NV4: 106.42 | NW4: 106.82 | NX4: 107.03 | NY4: 107.3 | NZ4: 108.14 | OA4: 109.7
A5: Indice des prix à la consommation - Base 2015 - Ensemble des ménages - France - Ensemble hors loyers et hors tabac | B5: 001763862 | C5: 15/04/2022 08:45 | E5: (O) | F5: (O) | G5: (O) | H5: (O) | I5: (O) | J5: (O) | K5: (O) | L5: (O) | M5: (O) | N5: (O) | O5: (O) | P5: (O) | Q5: (O) | R5: (O) | S5: (O) | T5: (O) | U5: (O) | V5: (O) | W5: (O) | X5: (O) | Y5: (O) | Z5: (O) | AA5: (O) | AB5: (O) | AC5: (O) | AD5: (O) | AE5: (O) | AF5: (O) | AG5: (O) | AH5: (O) | AI5: (O) | AJ5: (O) | AK5: (O) | AL5: (O) | AM5: (O) | AN5: (O) | AO5: (O) | AP5: (O) | AQ5: (O) | AR5: (O) | AS5: (O) | AT5: (O) | AU5: (O) | AV5: (O) | AW5: (O) | AX5: (O) | AY5: (O) | AZ5: (O) | BA5: (O) | BB5: (O) | BC5: (O) | BD5: (O) | BE5: (O) | BF5: (O) | BG5: (O) | BH5: (O) | BI5: (O) | BJ5: (O) | BK5: (O) | BL5: (O) | BM5: (O) | BN5: (O) | BO5: (O) | BP5: (O) | BQ5: (O) | BR5: (O) | BS5: (O) | BT5: (O) | BU5: (O) | BV5: (O) | BW5: (O) | BX5: (O) | BY5: (O) | BZ5: (O) | CA5: (O) | CB5: (O) | CC5: (O) | CD5: (O) | CE5: (O) | CF5: (O) | CG5: (O) | CH5: (O) | CI5: (O) | CJ5: (O) | CK5: (O) | CL5: (O) | CM5: (O) | CN5: (O) | CO5: (O) | CP5: (O) | CQ5: (O) | CR5: (O) | CS5: (O) | CT5: (O) | CU5: (O) | CV5: (O) | CW5: 79.42 | CX5: 79.73 | CY5: 79.87 | CZ5: 80.03 | DA5: 80.05 | DB5: 80.11 | DC5: 79.81 | DD5: 79.85 | DE5: 79.81 | DF5: 79.74 | DG5: 79.68 | DH5: 79.77 | DI5: 79.45 | DJ5: 79.71 | DK5: 79.99 | DL5: 80.22 | DM5: 80.22 | DN5: 80.21 | DO5: 79.98 | DP5: 80.11 | DQ5: 80.24 | DR5: 80.3 | DS5: 80.33 | DT5: 80.71 | DU5: 80.7 | DV5: 80.8 | DW5: 81.2 | DX5: 81.2 | DY5: 81.37 | DZ5: 81.59 | EA5: 81.44 | EB5: 81.6 | EC5: 82.04 | ED5: 81.94 | EE5: 82.13 | EF5: 82.09 | EG5: 81.68 | EH5: 81.9 | EI5: 82.29 | EJ5: 82.71 | EK5: 83.26 | EL5: 83.31 | EM5: 83.12 | EN5: 83.12 | EO5: 83.27 | EP5: 83.31 | EQ5: 83.06 | ER5: 83.16 | ES5: 83.42 | ET5: 83.52 | EU5: 83.9 | EV5: 84.22 | EW5: 84.32 | EX5: 84.3 | EY5: 84.3 | EZ5: 84.49 | FA5: 84.65 | FB5: 84.77 | FC5: 84.77 | FD5: 84.91 | FE5: 84.9 | FF5: 85.5 | FG5: 85.86 | FH5: 85.71 | FI5: 85.59 | FJ5: 85.76 | FK5: 85.66 | FL5: 85.87 | FM5: 86.21 | FN5: 86.25 | FO5: 86.12 | FP5: 86.21 | FQ5: 86.04 | FR5: 86.4 | FS5: 86.75 | FT5: 86.98 | FU5: 87.32 | FV5: 87.35 | FW5: 87.18 | FX5: 87.36 | FY5: 87.43 | FZ5: 87.66 | GA5: 87.69 | GB5: 87.78 | GC5: 87.25 | GD5: 87.81 | GE5: 88.4 | GF5: 88.55 | GG5: 88.6 | GH5: 88.7 | GI5: 88.54 | GJ5: 88.89 | GK5: 89.24 | GL5: 89.22 | GM5: 89 | GN5: 89.1 | GO5: 88.99 | GP5: 89.33 | GQ5: 89.58 | GR5: 89.98 | GS5: 90.39 | GT5: 90.37 | GU5: 90.2 | GV5: 90.51 | GW5: 90.28 | GX5: 90.05 | GY5: 90.15 | GZ5: 90.36 | HA5: 90 | HB5: 90.17 | HC5: 90.57 | HD5: 91.01 | HE5: 91.25 | HF5: 91.36 | HG5: 91.1 | HH5: 91.4 | HI5: 91.47 | HJ5: 91.71 | HK5: 92.24 | HL5: 92.6 | HM5: 92.48 | HN5: 92.68 | HO5: 93.42 | HP5: 93.76 | HQ5: 94.29 | HR5: 94.66 | HS5: 94.44 | HT5: 94.39 | HU5: 94.3 | HV5: 94.23 | HW5: 93.74 | HX5: 93.49 | HY5: 93.07 | HZ5: 93.44 | IA5: 93.61 | IB5: 93.75 | IC5: 93.89 | ID5: 94.01 | IE5: 93.55 | IF5: 94.05 | IG5: 93.79 | IH5: 93.89 | II5: 93.95 | IJ5: 94.19 | IK5: 93.95 | IL5: 94.5 | IM5: 94.99 | IN5: 95.25 | IO5: 95.36 | IP5: 95.34 | IQ5: 95.05 | IR5: 95.29 | IS5: 95.2 | IT5: 95.34 | IU5: 95.37 | IV5: 95.81 | IW5: 95.57 | IX5: 96.04 | IY5: 96.88 | IZ5: 97.23 | JA5: 97.29 | JB5: 97.36 | JC5: 96.89 | JD5: 97.43 | JE5: 97.34 | JF5: 97.54 | JG5: 97.76 | JH5: 98.18 | JI5: 97.8 | JJ5: 98.22 | JK5: 99.1 | JL5: 99.22 | JM5: 99.15 | JN5: 99.19 | JO5: 98.72 | JP5: 99.42 | JQ5: 99.14 | JR5: 99.19 | JS5: 99.02 | JT5: 99.35 | JU5: 98.79 | JV5: 99.06 | JW5: 99.88 | JX5: 99.72 | JY5: 99.77 | JZ5: 99.94 | KA5: 99.57 | KB5: 100.03 | KC5: 99.77 | KD5: 99.63 | KE5: 99.58 | KF5: 99.95 | KG5: 99.29 | KH5: 99.83 | KI5: 100.31 | KJ5: 100.27 | KK5: 100.29 | KL5: 100.25 | KM5: 99.9 | KN5: 100.37 | KO5: 99.95 | KP5: 99.98 | KQ5: 99.79 | KR5: 99.88 | KS5: 98.79 | KT5: 99.49 | KU5: 100.19 | KV5: 100.31 | KW5: 100.57 | KX5: 100.48 | KY5: 100.03 | KZ5: 100.37 | LA5: 99.94 | LB5: 100 | LC5: 99.79 | LD5: 100.03 | LE5: 98.99 | LF5: 99.25 | LG5: 100 | LH5: 100.08 | LI5: 100.52 | LJ5: 100.66 | LK5: 100.25 | LL5: 100.61 | LM5: 100.34 | LN5: 100.37 | LO5: 100.35 | LP5: 100.68 | LQ5: 100.41 | LR5: 100.53 | LS5: 101.19 | LT5: 101.28 | LU5: 101.34 | LV5: 101.35 | LW5: 100.97 | LX5: 101.54 | LY5: 101.36 | LZ5: 101.46 | MA5: 101.53 | MB5: 101.84 | MC5: 101.74 | MD5: 101.69 | ME5: 102.53 | MF5: 102.71 | MG5: 103.2 | MH5: 103.29 | MI5: 103.18 | MJ5: 103.74 | MK5: 103.49 | ML5: 103.61 | MM5: 103.37 | MN5: 103.38 | MO5: 102.86 | MP5: 102.88 | MQ5: 103.62 | MR5: 103.97 | MS5: 104.08 | MT5: 104.35 | MU5: 104.13 | MV5: 104.64 | MW5: 104.25 | MX5: 104.2 | MY5: 104.12 | MZ5: 104.62 | NA5: 104.14 | NB5: 104.13 | NC5: 104.03 | ND5: 104 | NE5: 104.16 | NF5: 104.25 | NG5: 104.67 | NH5: 104.57 | NI5: 103.98 | NJ5: 103.93 | NK5: 104.05 | NL5: 104.29 | NM5: 104.45 | NN5: 104.4 | NO5: 105.09 | NP5: 105.2 | NQ5: 105.58 | NR5: 105.73 | NS5: 105.8 | NT5: 106.5 | NU5: 106.25 | NV5: 106.73 | NW5: 107.18 | NX5: 107.4 | NY5: 107.69 | NZ5: 108.56 | OA5: 110.24
A7: Libellé | B7: idBank | C7: Dernière mise à jour | D7: Période | E7: 1990-01 | F7: 1990-02 | G7: 1990-03 | H7: 1990-04 | I7: 1990-05 | J7: 1990-06 | K7: 1990-07 | L7: 1990-08 | M7: 1990-09 | N7: 1990-10 | O7: 1990-11 | P7: 1990-12 | Q7: 1991-01 | R7: 1991-02 | S7: 1991-03 | T7: 1991-04 | U7: 1991-05 | V7: 1991-06 | W7: 1991-07 | X7: 1991-08 | Y7: 1991-09 | Z7: 1991-10 | AA7: 1991-11 | AB7: 1991-12 | AC7: 1992-01 | AD7: 1992-02 | AE7: 1992-03 | AF7: 1992-04 | AG7: 1992-05 | AH7: 1992-06 | AI7: 1992-07 | AJ7: 1992-08 | AK7: 1992-09 | AL7: 1992-10 | AM7: 1992-11 | AN7: 1992-12 | AO7: 1993-01 | AP7: 1993-02 | AQ7: 1993-03 | AR7: 1993-04 | AS7: 1993-05 | AT7: 1993-06 | AU7: 1993-07 | AV7: 1993-08 | AW7: 1993-09 | AX7: 1993-10 | AY7: 1993-11 | AZ7: 1993-12 | BA7: 1994-01 | BB7: 1994-02 | BC7: 1994-03 | BD7: 1994-04 | BE7: 1994-05 | BF7: 1994-06 | BG7: 1994-07 | BH7: 1994-08 | BI7: 1994-09 | BJ7: 1994-10 | BK7: 1994-11 | BL7: 1994-12 | BM7: 1995-01 | BN7: 1995-02 | BO7: 1995-03 | BP7: 1995-04 | BQ7: 1995-05 | BR7: 1995-06 | BS7: 1995-07 | BT7: 1995-08 | BU7: 1995-09 | BV7: 1995-10 | BW7: 1995-11 | BX7: 1995-12 | BY7: 1996-01 | BZ7: 1996-02 | CA7: 1996-03 | CB7: 1996-04 | CC7: 1996-05 | CD7: 1996-06 | CE7: 1996-07 | CF7: 1996-08 | CG7: 1996-09 | CH7: 1996-10 | CI7: 1996-11 | CJ7: 1996-12 | CK7: 1997-01 | CL7: 1997-02 | CM7: 1997-03 | CN7: 1997-04 | CO7: 1997-05 | CP7: 1997-06 | CQ7: 1997-07 | CR7: 1997-08 | CS7: 1997-09 | CT7: 1997-10 | CU7: 1997-11 | CV7: 1997-12 | CW7: 1998-01 | CX7: 1998-02 | CY7: 1998-03 | CZ7: 1998-04 | DA7: 1998-05 | DB7: 1998-06 | DC7: 1998-07 | DD7: 1998-08 | DE7: 1998-09 | DF7: 1998-10 | DG7: 1998-11 | DH7: 1998-12 | DI7: 1999-01 | DJ7: 1999-02 | DK7: 1999-03 | DL7: 1999-04 | DM7: 1999-05 | DN7: 1999-06 | DO7: 1999-07 | DP7: 1999-08 | DQ7: 1999-09 | DR7: 1999-10 | DS7: 1999-11 | DT7: 1999-12 | DU7: 2000-01 | DV7: 2000-02 | DW7: 2000-03 | DX7: 2000-04 | DY7: 2000-05 | DZ7: 2000-06 | EA7: 2000-07 | EB7: 2000-08 | EC7: 2000-09 | ED7: 2000-10 | EE7: 2000-11 | EF7: 2000-12 | EG7: 2001-01 | EH7: 2001-02 | EI7: 2001-03 | EJ7: 2001-04 | EK7: 2001-05 | EL7: 2001-06 | EM7: 2001-07 | EN7: 2001-08 | EO7: 2001-09 | EP7: 2001-10 | EQ7: 2001-11 | ER7: 2001-12 | ES7: 2002-01 | ET7: 2002-02 | EU7: 2002-03 | EV7: 2002-04 | EW7: 2002-05 | EX7: 2002-06 | EY7: 2002-07 | EZ7: 2002-08 | FA7: 2002-09 | FB7: 2002-10 | FC7: 2002-11 | FD7: 2002-12 | FE7: 2003-01 | FF7: 2003-02 | FG7: 2003-03 | FH7: 2003-04 | FI7: 2003-05 | FJ7: 2003-06 | FK7: 2003-07 | FL7: 2003-08 | FM7: 2003-09 | FN7: 2003-10 | FO7: 2003-11 | FP7: 2003-12 | FQ7: 2004-01 | FR7: 2004-02 | FS7: 2004-03 | FT7: 2004-04 | FU7: 2004-05 | FV7: 2004-06 | FW7: 2004-07 | FX7: 2004-08 | FY7: 2004-09 | FZ7: 2004-10 | GA7: 2004-11 | GB7: 2004-12 | GC7: 2005-01 | GD7: 2005-02 | GE7: 2005-03 | GF7: 2005-04 | GG7: 2005-05 | GH7: 2005-06 | GI7: 2005-07 | GJ7: 2005-08 | GK7: 2005-09 | GL7: 2005-10 | GM7: 2005-11 | GN7: 2005-12 | GO7: 2006-01 | GP7: 2006-02 | GQ7: 2006-03 | GR7: 2006-04 | GS7: 2006-05 | GT7: 2006-06 | GU7: 2006-07 | GV7: 2006-08 | GW7: 2006-09 | GX7: 2006-10 | GY7: 2006-11 | GZ7: 2006-12 | HA7: 2007-01 | HB7: 2007-02 | HC7: 2007-03 | HD7: 2007-04 | HE7: 2007-05 | HF7: 2007-06 | HG7: 2007-07 | HH7: 2007-08 | HI7: 2007-09 | HJ7: 2007-10 | HK7: 2007-11 | HL7: 2007-12 | HM7: 2008-01 | HN7: 2008-02 | HO7: 2008-03 | HP7: 2008-04 | HQ7: 2008-05 | HR7: 2008-06 | HS7: 2008-07 | HT7: 2008-08 | HU7: 2008-09 | HV7: 2008-10 | HW7: 2008-11 | HX7: 2008-12 | HY7: 2009-01 | HZ7: 2009-02 | IA7: 2009-03 | IB7: 2009-04 | IC7: 2009-05 | ID7: 2009-06 | IE7: 2009-07 | IF7: 2009-08 | IG7: 2009-09 | IH7: 2009-10 | II7: 2009-11 | IJ7: 2009-12 | IK7: 2010-01 | IL7: 2010-02 | IM7: 2010-03 | IN7: 2010-04 | IO7: 2010-05 | IP7: 2010-06 | IQ7: 2010-07 | IR7: 2010-08 | IS7: 2010-09 | IT7: 2010-10 | IU7: 2010-11 | IV7: 2010-12 | IW7: 2011-01 | IX7: 2011-02 | IY7: 2011-03 | IZ7: 2011-04 | JA7: 2011-05 | JB7: 2011-06 | JC7: 2011-07 | JD7: 2011-08 | JE7: 2011-09 | JF7: 2011-10 | JG7: 2011-11 | JH7: 2011-12 | JI7: 2012-01 | JJ7: 2012-02 | JK7: 2012-03 | JL7: 2012-04 | JM7: 2012-05 | JN7: 2012-06 | JO7: 2012-07 | JP7: 2012-08 | JQ7: 2012-09 | JR7: 2012-10 | JS7: 2012-11 | JT7: 2012-12 | JU7: 2013-01 | JV7: 2013-02 | JW7: 2013-03 | JX7: 2013-04 | JY7: 2013-05 | JZ7: 2013-06 | KA7: 2013-07 | KB7: 2013-08 | KC7: 2013-09 | KD7: 2013-10 | KE7: 2013-11 | KF7: 2013-12 | KG7: 2014-01 | KH7: 2014-02 | KI7: 2014-03 | KJ7: 2014-04 | KK7: 2014-05 | KL7: 2014-06 | KM7: 2014-07 | KN7: 2014-08 | KO7: 2014-09 | KP7: 2014-10 | KQ7: 2014-11 | KR7: 2014-12 | KS7: 2015-01 | KT7: 2015-02 | KU7: 2015-03 | KV7: 2015-04 | KW7: 2015-05 | KX7: 2015-06 | KY7: 2015-07 | KZ7: 2015-08 | LA7: 2015-09 | LB7: 2015-10 | LC7: 2015-11 | LD7: 2015-12 | LE7: 2016-01 | LF7: 2016-02 | LG7: 2016-03 | LH7: 2016-04 | LI7: 2016-05 | LJ7: 2016-06 | LK7: 2016-07 | LL7: 2016-08 | LM7: 2016-09 | LN7: 2016-10 | LO7: 2016-11 | LP7: 2016-12 | LQ7: 2017-01 | LR7: 2017-02 | LS7: 2017-03 | LT7: 2017-04 | LU7: 2017-05 | LV7: 2017-06 | LW7: 2017-07 | LX7: 2017-08 | LY7: 2017-09 | LZ7: 2017-10 | MA7: 2017-11 | MB7: 2017-12 | MC7: 2018-01 | MD7: 2018-02 | ME7: 2018-03 | MF7: 2018-04 | MG7: 2018-05 | MH7: 2018-06 | MI7: 2018-07 | MJ7: 2018-08 | MK7: 2018-09 | ML7: 2018-10 | MM7: 2018-11 | MN7: 2018-12 | MO7: 2019-01 | MP7: 2019-02 | MQ7: 2019-03 | MR7: 2019-04 | MS7: 2019-05 | MT7: 2019-06 | MU7: 2019-07 | MV7: 2019-08 | MW7: 2019-09 | MX7: 2019-10 | MY7: 2019-11 | MZ7: 2019-12 | NA7: 2020-01 | NB7: 2020-02 | NC7: 2020-03 | ND7: 2020-04 | NE7: 2020-05 | NF7: 2020-06 | NG7: 2020-07 | NH7: 2020-08 | NI7: 2020-09 | NJ7: 2020-10 | NK7: 2020-11 | NL7: 2020-12 | NM7: 2021-01 | NN7: 2021-02 | NO7: 2021-03 | NP7: 2021-04 | NQ7: 2021-05 | NR7: 2021-06 | NS7: 2021-07 | NT7: 2021-08 | NU7: 2021-09 | NV7: 2021-10 | NW7: 2021-11 | NX7: 2021-12 | NY7: 2022-01 | NZ7: 2022-02 | OA7: 2022-03
A8: Indice CVS des prix à la consommation - Base 2015 - Ensemble des ménages - France - Ensemble | B8: 001769682 | C8: 15/04/2022 08:45 | F8: =F2/E2-1 -> 0 | G8: =G2/F2-1 -> 0 | H8: =H2/G2-1 -> 0.006006006 | I8: =I2/H2-1 -> 0 | J8: =J2/I2-1 -> 0.0029850746 | K8: =K2/J2-1 -> 0.0014880952 | L8: =L2/K2-1 -> 0.0074294205 | M8: =M2/L2-1 -> 0.005899705 | ... OA8: =OA2/NZ2-1 -> 0.0096989661
A9: Indice des prix à la consommation - Base 2015 - Ensemble des ménages - France - Ensemble hors énergie | B9: 001763851 | C9: 15/04/2022 08:45 | F9: =F3/E3-1 -> 0.0028007075 | G9: =G3/F3-1 -> 0.0029398795 | H9: =H3/G3-1 -> 0.0063022131 | I9: =I3/H3-1 -> 0.0017477425 | J9: =J3/I3-1 -> 0.0002907822 | K9: =K3/J3-1 -> 0.00029069767 | L9: =L3/K3-1 -> 0.0027608253 | M9: =M3/L3-1 -> 0.0027532242 | ... OA9: =OA3/NZ3-1 -> 0.0063730084
A10: Indice des prix à la consommation - Base 2015 - Ensemble des ménages - France - Ensemble hors tabac | B10: 001763852 | C10: 15/04/2022 08:45 | F10: =F4/E4-1 -> 0.0020561022 | G10: =G4/F4-1 -> 0.0024915726 | H10: =H4/G4-1 -> 0.0055555556 | I10: =I4/H4-1 -> 0.0015993021 | J10: =J4/I4-1 -> -0.00014515895 | K10: =K4/J4-1 -> 0.00029036005 | L10: =L4/K4-1 -> 0.0066763425 | M10: =M4/L4-1 -> 0.0072087659 | ... OA10: =OA4/NZ4-1 -> 0.014425744
A11: Indice des prix à la consommation - Base 2015 - Ensemble des ménages - France - Ensemble hors loyers et hors tabac | B11: 001763862 | C11: 15/04/2022 08:45 | F11: =F5/E5-1 -> #VALUE! | G11: =G5/F5-1 -> #VALUE! | H11: =H5/G5-1 -> #VALUE! | I11: =I5/H5-1 -> #VALUE! | J11: =J5/I5-1 -> #VALUE! | K11: =K5/J5-1 -> #VALUE! | L11: =L5/K5-1 -> #VALUE! | M11: =M5/L5-1 -> #VALUE! | ... OA11: =OA5/NZ5-1 -> 0.015475313
A13: Libellé | B13: idBank | C13: Dernière mise à jour | D13: Période | E13: 1990-01 | F13: 1990-02 | G13: 1990-03 | H13: 1990-04 | I13: 1990-05 | J13: 1990-06 | K13: 1990-07 | L13: 1990-08 | M13: 1990-09 | N13: 1990-10 | O13: 1990-11 | P13: 1990-12 | Q13: 1991-01 | R13: 1991-02 | S13: 1991-03 | T13: 1991-04 | U13: 1991-05 | V13: 1991-06 | W13: 1991-07 | X13: 1991-08 | Y13: 1991-09 | Z13: 1991-10 | AA13: 1991-11 | AB13: 1991-12 | AC13: 1992-01 | AD13: 1992-02 | AE13: 1992-03 | AF13: 1992-04 | AG13: 1992-05 | AH13: 1992-06 | AI13: 1992-07 | AJ13: 1992-08 | AK13: 1992-09 | AL13: 1992-10 | AM13: 1992-11 | AN13: 1992-12 | AO13: 1993-01 | AP13: 1993-02 | AQ13: 1993-03 | AR13: 1993-04 | AS13: 1993-05 | AT13: 1993-06 | AU13: 1993-07 | AV13: 1993-08 | AW13: 1993-09 | AX13: 1993-10 | AY13: 1993-11 | AZ13: 1993-12 | BA13: 1994-01 | BB13: 1994-02 | BC13: 1994-03 | BD13: 1994-04 | BE13: 1994-05 | BF13: 1994-06 | BG13: 1994-07 | BH13: 1994-08 | BI13: 1994-09 | BJ13: 1994-10 | BK13: 1994-11 | BL13: 1994-12 | BM13: 1995-01 | BN13: 1995-02 | BO13: 1995-03 | BP13: 1995-04 | BQ13: 1995-05 | BR13: 1995-06 | BS13: 1995-07 | BT13: 1995-08 | BU13: 1995-09 | BV13: 1995-10 | BW13: 1995-11 | BX13: 1995-12 | BY13: 1996-01 | BZ13: 1996-02 | CA13: 1996-03 | CB13: 1996-04 | CC13: 1996-05 | CD13: 1996-06 | CE13: 1996-07 | CF13: 1996-08 | CG13: 1996-09 | CH13: 1996-10 | CI13: 1996-11 | CJ13: 1996-12 | CK13: 1997-01 | CL13: 1997-02 | CM13: 1997-03 | CN13: 1997-04 | CO13: 1997-05 | CP13: 1997-06 | CQ13: 1997-07 | CR13: 1997-08 | CS13: 1997-09 | CT13: 1997-10 | CU13: 1997-11 | CV13: 1997-12 | CW13: 1998-01 | CX13: 1998-02 | CY13: 1998-03 | CZ13: 1998-04 | DA13: 1998-05 | DB13: 1998-06 | DC13: 1998-07 | DD13: 1998-08 | DE13: 1998-09 | DF13: 1998-10 | DG13: 1998-11 | DH13: 1998-12 | DI13: 1999-01 | DJ13: 1999-02 | DK13: 1999-03 | DL13: 1999-04 | DM13: 1999-05 | DN13: 1999-06 | DO13: 1999-07 | DP13: 1999-08 | DQ13: 1999-09 | DR13: 1999-10 | DS13: 1999-11 | DT13: 1999-12 | DU13: 2000-01 | DV13: 2000-02 | DW13: 2000-03 | DX13: 2000-04 | DY13: 2000-05 | DZ13: 2000-06 | EA13: 2000-07 | EB13: 2000-08 | EC13: 2000-09 | ED13: 2000-10 | EE13: 2000-11 | EF13: 2000-12 | EG13: 2001-01 | EH13: 2001-02 | EI13: 2001-03 | EJ13: 2001-04 | EK13: 2001-05 | EL13: 2001-06 | EM13: 2001-07 | EN13: 2001-08 | EO13: 2001-09 | EP13: 2001-10 | EQ13: 2001-11 | ER13: 2001-12 | ES13: 2002-01 | ET13: 2002-02 | EU13: 2002-03 | EV13: 2002-04 | EW13: 2002-05 | EX13: 2002-06 | EY13: 2002-07 | EZ13: 2002-08 | FA13: 2002-09 | FB13: 2002-10 | FC13: 2002-11 | FD13: 2002-12 | FE13: 2003-01 | FF13: 2003-02 | FG13: 2003-03 | FH13: 2003-04 | FI13: 2003-05 | FJ13: 2003-06 | FK13: 2003-07 | FL13: 2003-08 | FM13: 2003-09 | FN13: 2003-10 | FO13: 2003-11 | FP13: 2003-12 | FQ13: 2004-01 | FR13: 2004-02 | FS13: 2004-03 | FT13: 2004-04 | FU13: 2004-05 | FV13: 2004-06 | FW13: 2004-07 | FX13: 2004-08 | FY13: 2004-09 | FZ13: 2004-10 | GA13: 2004-11 | GB13: 2004-12 | GC13: 2005-01 | GD13: 2005-02 | GE13: 2005-03 | GF13: 2005-04 | GG13: 2005-05 | GH13: 2005-06 | GI13: 2005-07 | GJ13: 2005-08 | GK13: 2005-09 | GL13: 2005-10 | GM13: 2005-11 | GN13: 2005-12 | GO13: 2006-01 | GP13: 2006-02 | GQ13: 2006-03 | GR13: 2006-04 | GS13: 2006-05 | GT13: 2006-06 | GU13: 2006-07 | GV13: 2006-08 | GW13: 2006-09 | GX13: 2006-10 | GY13: 2006-11 | GZ13: 2006-12 | HA13: 2007-01 | HB13: 2007-02 | HC13: 2007-03 | HD13: 2007-04 | HE13: 2007-05 | HF13: 2007-06 | HG13: 2007-07 | HH13: 2007-08 | HI13: 2007-09 | HJ13: 2007-10 | HK13: 2007-11 | HL13: 2007-12 | HM13: 2008-01 | HN13: 2008-02 | HO13: 2008-03 | HP13: 2008-04 | HQ13: 2008-05 | HR13: 2008-06 | HS13: 2008-07 | HT13: 2008-08 | HU13: 2008-09 | HV13: 2008-10 | HW13: 2008-11 | HX13: 2008-12 | HY13: 2009-01 | HZ13: 2009-02 | IA13: 2009-03 | IB13: 2009-04 | IC13: 2009-05 | ID13: 2009-06 | IE13: 2009-07 | IF13: 2009-08 | IG13: 2009-09 | IH13: 2009-10 | II13: 2009-11 | IJ13: 2009-12 | IK13: 2010-01 | IL13: 2010-02 | IM13: 2010-03 | IN13: 2010-04 | IO13: 2010-05 | IP13: 2010-06 | IQ13: 2010-07 | IR13: 2010-08 | IS13: 2010-09 | IT13: 2010-10 | IU13: 2010-11 | IV13: 2010-12 | IW13: 2011-01 | IX13: 2011-02 | IY13: 2011-03 | IZ13: 2011-04 | JA13: 2011-05 | JB13: 2011-06 | JC13: 2011-07 | JD13: 2011-08 | JE13: 2011-09 | JF13: 2011-10 | JG13: 2011-11 | JH13: 2011-12 | JI13: 2012-01 | JJ13: 2012-02 | JK13: 2012-03 | JL13: 2012-04 | JM13: 2012-05 | JN13: 2012-06 | JO13: 2012-07 | JP13: 2012-08 | JQ13: 2012-09 | JR13: 2012-10 | JS13: 2012-11 | JT13: 2012-12 | JU13: 2013-01 | JV13: 2013-02 | JW13: 2013-03 | JX13: 2013-04 | JY13: 2013-05 | JZ13: 2013-06 | KA13: 2013-07 | KB13: 2013-08 | KC13: 2013-09 | KD13: 2013-10 | KE13: 2013-11 | KF13: 2013-12 | KG13: 2014-01 | KH13: 2014-02 | KI13: 2014-03 | KJ13: 2014-04 | KK13: 2014-05 | KL13: 2014-06 | KM13: 2014-07 | KN13: 2014-08 | KO13: 2014-09 | KP13: 2014-10 | KQ13: 2014-11 | KR13: 2014-12 | KS13: 2015-01 | KT13: 2015-02 | KU13: 2015-03 | KV13: 2015-04 | KW13: 2015-05 | KX13: 2015-06 | KY13: 2015-07 | KZ13: 2015-08 | LA13: 2015-09 | LB13: 2015-10 | LC13: 2015-11 | LD13: 2015-12 | LE13: 2016-01 | LF13: 2016-02 | LG13: 2016-03 | LH13: 2016-04 | LI13: 2016-05 | LJ13: 2016-06 | LK13: 2016-07 | LL13: 2016-08 | LM13: 2016-09 | LN13: 2016-10 | LO13: 2016-11 | LP13: 2016-12 | LQ13: 2017-01 | LR13: 2017-02 | LS13: 2017-03 | LT13: 2017-04 | LU13: 2017-05 | LV13: 2017-06 | LW13: 2017-07 | LX13: 2017-08 | LY13: 2017-09 | LZ13: 2017-10 | MA13: 2017-11 | MB13: 2017-12 | MC13: 2018-01 | MD13: 2018-02 | ME13: 2018-03 | MF13: 2018-04 | MG13: 2018-05 | MH13: 2018-06 | MI13: 2018-07 | MJ13: 2018-08 | MK13: 2018-09 | ML13: 2018-10 | MM13: 2018-11 | MN13: 2018-12 | MO13: 2019-01 | MP13: 2019-02 | MQ13: 2019-03 | MR13: 2019-04 | MS13: 2019-05 | MT13: 2019-06 | MU13: 2019-07 | MV13: 2019-08 | MW13: 2019-09 | MX13: 2019-10 | MY13: 2019-11 | MZ13: 2019-12 | NA13: 2020-01 | NB13: 2020-02 | NC13: 2020-03 | ND13: 2020-04 | NE13: 2020-05 | NF13: 2020-06 | NG13: 2020-07 | NH13: 2020-08 | NI13: 2020-09 | NJ13: 2020-10 | NK13: 2020-11 | NL13: 2020-12 | NM13: 2021-01 | NN13: 2021-02 | NO13: 2021-03 | NP13: 2021-04 | NQ13: 2021-05 | NR13: 2021-06 | NS13: 2021-07 | NT13: 2021-08 | NU13: 2021-09 | NV13: 2021-10 | NW13: 2021-11 | NX13: 2021-12 | NY13: 2022-01 | NZ13: 2022-02 | OA13: 2022-03
A14: Indice CVS des prix à la consommation - Base 2015 - Ensemble des ménages - France - Ensemble | B14: 001769682 | C14: 15/04/2022 08:45 | Q14: =Q2/E2-1 -> 0.033033033 | R14: =R2/F2-1 -> 0.033033033 | S14: =S2/G2-1 -> 0.033033033 | T14: =T2/H2-1 -> 0.031343284 | U14: =U2/I2-1 -> 0.032835821 | V14: =V2/J2-1 -> 0.03422619 | W14: =W2/K2-1 -> 0.037147103 | X14: =X2/L2-1 -> 0.032448378 | ... OA14: =OA2/NO2-1 -> 0.045179011
A15: Indice des prix à la consommation - Base 2015 - Ensemble des ménages - France - Ensemble hors énergie | B15: 001763851 | C15: 15/04/2022 08:45 | Q15: =Q3/E3-1 -> 0.031102594 | R15: =R3/F3-1 -> 0.031603704 | S15: =S3/G3-1 -> 0.032390444 | T15: =T3/H3-1 -> 0.029857268 | U15: =U3/I3-1 -> 0.031113696 | V15: =V3/J3-1 -> 0.033139535 | W15: =W3/K3-1 -> 0.03545481 | X15: =X3/L3-1 -> 0.033328503 | ... OA15: =OA3/NO3-1 -> 0.023153883
A16: Indice des prix à la consommation - Base 2015 - Ensemble des ménages - France - Ensemble hors tabac | B16: 001763852 | C16: 15/04/2022 08:45 | Q16: =Q4/E4-1 -> 0.033778822 | R16: =R4/F4-1 -> 0.034442327 | S16: =S4/G4-1 -> 0.033918129 | T16: =T4/H4-1 -> 0.031404478 | U16: =U4/I4-1 -> 0.03309624 | V16: =V4/J4-1 -> 0.035714286 | W16: =W4/K4-1 -> 0.038171263 | X16: =X4/L4-1 -> 0.032583622 | ... OA16: =OA4/NO4-1 -> 0.045857565
A17: Indice des prix à la consommation - Base 2015 - Ensemble des ménages - France - Ensemble hors loyers et hors tabac | B17: 001763862 | C17: 15/04/2022 08:45 | Q17: =Q5/E5-1 -> #VALUE! | R17: =R5/F5-1 -> #VALUE! | S17: =S5/G5-1 -> #VALUE! | T17: =T5/H5-1 -> #VALUE! | U17: =U5/I5-1 -> #VALUE! | V17: =V5/J5-1 -> #VALUE! | W17: =W5/K5-1 -> #VALUE! | X17: =X5/L5-1 -> #VALUE! | ... OA17: =OA5/NO5-1 -> 0.049005614
A19: Libellé | B19: idBank | C19: Dernière mise à jour | D19: Période
A20: Indice de référence des loyers (IRL) - Variation annuelle | B20: 001515334 | C20: 15/04/2022 08:45 | LU20: 2017-T1 | LV20: =+LU20 -> 2017-T1 | LW20: =+LV20 -> 2017-T1 | LX20: 2017-T2 | LY20: =+LX20 -> 2017-T2 | LZ20: =+LY20 -> 2017-T2 | MA20: 2017-T3 | MB20: =+MA20 -> 2017-T3 | MC20: =+MB20 -> 2017-T3 | MD20: 2017-T4 | ME20: =+MD20 -> 2017-T4 | MF20: =+ME20 -> 2017-T4 | MG20: 2018-T1 | MH20: =+MG20 -> 2018-T1 | MI20: =+MH20 -> 2018-T1 | MJ20: 2018-T2 | MK20: =+MJ20 -> 2018-T2 | ML20: =+MK20 -> 2018-T2 | MM20: 2018-T3 | MN20: =+MM20 -> 2018-T3 | MO20: =+MN20 -> 2018-T3 | MP20: 2018-T4 | MQ20: =+MP20 -> 2018-T4 | MR20: =+MQ20 -> 2018-T4 | MS20: 2019-T1 | MT20: =+MS20 -> 2019-T1 | MU20: =+MT20 -> 2019-T1 | MV20: 2019-T2 | MW20: =+MV20 -> 2019-T2 | MX20: =+MW20 -> 2019-T2 | MY20: 2019-T3 | MZ20: =+MY20 -> 2019-T3 | NA20: =+MZ20 -> 2019-T3 | NB20: 2019-T4 | NC20: =+NB20 -> 2019-T4 | ND20: =+NC20 -> 2019-T4 | NE20: 2020-T1 | NF20: =+NE20 -> 2020-T1 | NG20: =+NF20 -> 2020-T1 | NH20: 2020-T2 | NI20: =+NH20 -> 2020-T2 | NJ20: =+NI20 -> 2020-T2 | NK20: 2020-T3 | NL20: =+NK20 -> 2020-T3 | NM20: =+NL20 -> 2020-T3 | NN20: 2020-T4 | NO20: =+NN20 -> 2020-T4 | NP20: =+NO20 -> 2020-T4 | NQ20: 2021-T1 | NR20: =+NQ20 -> 2021-T1 | NS20: =+NR20 -> 2021-T1 | NT20: 2021-T2 | NU20: =+NT20 -> 2021-T2 | NV20: =+NU20 -> 2021-T2 | NW20: 2021-T3 | NX20: =+NW20 -> 2021-T3 | NY20: =+NX20 -> 2021-T3 | NZ20: 2021-T4 | OA20: =+NZ20 -> 2021-T4 | OB20: =+OA20 -> 2021-T4 | OC20: 2022-T1 | OD20: =+OC20 -> 2022-T1 | OE20: =+OD20 -> 2022-T1
D21: Date de parution au JO | LU21: 0.51 | LV21: =+LU21 -> 0.51 | LW21: =+LV21 -> 0.51 | LX21: 0.75 | LY21: =+LX21 -> 0.75 | LZ21: =+LY21 -> 0.75 | MA21: 0.9 | MB21: =+MA21 -> 0.9 | MC21: =+MB21 -> 0.9 | MD21: 1.05 | ME21: =+MD21 -> 1.05 | MF21: =+ME21 -> 1.05 | MG21: 1.05 | MH21: =+MG21 -> 1.05 | MI21: =+MH21 -> 1.05 | MJ21: 1.25 | MK21: =+MJ21 -> 1.25 | ML21: =+MK21 -> 1.25 | MM21: 1.57 | MN21: =+MM21 -> 1.57 | MO21: =+MN21 -> 1.57 | MP21: 1.74 | MQ21: =+MP21 -> 1.74 | MR21: =+MQ21 -> 1.74 | MS21: 1.7 | MT21: =+MS21 -> 1.7 | MU21: =+MT21 -> 1.7 | MV21: 1.53 | MW21: =+MV21 -> 1.53 | MX21: =+MW21 -> 1.53 | MY21: 1.2 | MZ21: =+MY21 -> 1.2 | NA21: =+MZ21 -> 1.2 | NB21: 0.95 | NC21: =+NB21 -> 0.95 | ND21: =+NC21 -> 0.95 | NE21: 0.92 | NF21: =+NE21 -> 0.92 | NG21: =+NF21 -> 0.92 | NH21: 0.66 | NI21: =+NH21 -> 0.66 | NJ21: =+NI21 -> 0.66 | NK21: 0.46 | NL21: =+NK21 -> 0.46 | NM21: =+NL21 -> 0.46 | NN21: 0.2 | NO21: =+NN21 -> 0.2 | NP21: =+NO21 -> 0.2 | NQ21: 0.09 | NR21: =+NQ21 -> 0.09 | NS21: =+NR21 -> 0.09 | NT21: 0.42 | NU21: =+NT21 -> 0.42 | NV21: =+NU21 -> 0.42 | NW21: 0.83 | NX21: =+NW21 -> 0.83 | NY21: =+NX21 -> 0.83 | NZ21: 1.61 | OA21: =+NZ21 -> 1.61 | OB21: =+OA21 -> 1.61 | OC21: 2.48 | OD21: =+OC21 -> 2.48 | OE21: =+OD21 -> 2.48
LU22: 14/04/2017 | LV22: =+LU22 -> 14/04/2017 | LW22: =+LV22 -> 14/04/2017 | LX22: 16/07/2017 | LY22: =+LX22 -> 16/07/2017 | LZ22: =+LY22 -> 16/07/2017 | MA22: 13/10/2017 | MB22: =+MA22 -> 13/10/2017 | MC22: =+MB22 -> 13/10/2017 | MD22: 13/01/2018 | ME22: =+MD22 -> 13/01/2018 | MF22: =+ME22 -> 13/01/2018 | MG22: 13/04/2018 | MH22: =+MG22 -> 13/04/2018 | MI22: =+MH22 -> 13/04/2018 | MJ22: 13/07/2018 | MK22: =+MJ22 -> 13/07/2018 | ML22: =+MK22 -> 13/07/2018 | MM22: 28/11/2018 | MN22: =+MM22 -> 28/11/2018 | MO22: =+MN22 -> 28/11/2018 | MP22: 16/01/2019 | MQ22: =+MP22 -> 16/01/2019 | MR22: =+MQ22 -> 16/01/2019 | MS22: 12/04/2019 | MT22: =+MS22 -> 12/04/2019 | MU22: =+MT22 -> 12/04/2019 | MV22: 17/07/2019 | MW22: =+MV22 -> 17/07/2019 | MX22: =+MW22 -> 17/07/2019 | MY22: 16/10/2019 | MZ22: =+MY22 -> 16/10/2019 | NA22: =+MZ22 -> 16/10/2019 | NB22: 16/01/2020 | NC22: =+NB22 -> 16/01/2020 | ND22: =+NC22 -> 16/01/2020 | NE22: 25/06/2020 | NF22: =+NE22 -> 25/06/2020 | NG22: =+NF22 -> 25/06/2020 | NH22: 17/07/2020 | NI22: =+NH22 -> 17/07/2020 | NJ22: =+NI22 -> 17/07/2020 | NK22: 16/10/2020 | NL22: =+NK22 -> 16/10/2020 | NM22: =+NL22 -> 16/10/2020 | NN22: 17/01/2021 | NO22: =+NN22 -> 17/01/2021 | NP22: =+NO22 -> 17/01/2021 | NQ22: 17/04/2021 | NR22: =+NQ22 -> 17/04/2021 | NS22: =+NR22 -> 17/04/2021 | NT22: 16/07/2021 | NU22: =+NT22 -> 16/07/2021 | NV22: =+NU22 -> 16/07/2021 | NW22: 16/10/2021 | NX22: =+NW22 -> 16/10/2021 | NY22: =+NX22 -> 16/10/2021 | NZ22: 15/01/2022 | OA22: =+NZ22 -> 15/01/2022 | OB22: =+OA22 -> 15/01/2022 | OC22: 16/04/2022 | OD22: =+OC22 -> 16/04/2022 | OE22: =+OD22 -> 16/04/2022
